Workbook

Sheet 21.09.25
A2: ENTRADAS | B2: SALDO INICIAL | C2: INGRESOS | D2: TOTAL | E2: VENTA | F2: MENU | G2: MERMA/ VARIOS | H2: SALDO FINAL | I2: OBSERVACION
A3: TAMALES | D3: =B3+C3 -> 0 | E3: =IFERROR(VLOOKUP("TAMAL DE LA CASA CON ZARZA CRIOLLAL",J:K,2,FALSE),"0") -> 0 | H3: =D3-E3-F3-G3 -> 0 | J3: AJI DE GALLINA | K3: 5
A4: HUMITAS | B4: 0 | D4: =B4+C4 -> 0 | E4: =IFERROR(VLOOKUP("HUMITA DOÑA FRESIA C/AJI DE GALLINA",J:K,2,FALSE),"0") -> 0 | H4: =D4-E4-F4-G4 -> 0 | J4: AJIACO DE CUY(1/2 CUY) C/ARROZ | K4: 5
A5: PAPA RELLENA | B5: 0 | C5: 8 | D5: =B5+C5 -> 8 | E5: =IFERROR(VLOOKUP(A$5,J:K,2,FALSE),0)+IFERROR(VLOOKUP("PIQUEO PERUANISIMO",J:K,2,FALSE),0) -> 1 | H5: =D5-E5-F5-G5 -> 7 | J5: ARROZ C/MARISCOS | K5: 5 | M5: SE MERMO 2 PAPA RELLENAS
A6: SANGRECITA | B6: 2 | C6: 14 | D6: =B6+C6 -> 16 | E6: =IFERROR(VLOOKUP("SANGRECITA C/YUCA",J:K,2,FALSE),"0") -> 16 | H6: =D6-E6-F6-G6 -> 0 | J6: ARROZ C/PATO | K6: 4
A7: AJI DE GALLINA | B7: 7 | C7: 4 | D7: =B7+C7 -> 11 | E7: =IFERROR(VLOOKUP("HUMITA DOÑA FRESIA C/AJI DE GALLINA", J:K,2, FALSE)/2, 0) + IFERROR(VLOOKUP("AJI DE GALLINA",J:K,2, FALSE), 0) -> 5 | H7: =D7-E7-F7-G7 -> 6 | J7: ARROZ C/PATO DESHUESADO | K7: 8
A8: MOLLEJITA | B8: 4 | C8: 1 | D8: =B8+C8 -> 5 | E8: =IFERROR(VLOOKUP("MOLLEJITAS GUISADAS",J:K,2,FALSE),"0")+IFERROR(VLOOKUP("PIQUEO DOÑA FRESIA",J:K,2,FALSE),0) -> 3 | H8: =D8-E8-F8-G8 -> 2 | J8: ASADO DE RES CON ARROZ Y PURE | K8: 12
A9: PATITA | B9: 7 | C9: 1 | D9: =B9+C9 -> 8 | E9: =IFERROR(VLOOKUP("1/2 PATITA EN FIAMBRE",J:K,2, FALSE)/2, 0) + IFERROR(VLOOKUP("PATITA EN FIAMBRE",J:K, 2, FALSE), 0) -> 8 | H9: =D9-E9-F9-G9 -> 0 | J9: BISTEC DE LOMO FINO A LO POBRE | K9: 1
A10: CECINA | B10: 0.5 | C10: 4 | D10: =B10+C10 -> 4.5 | E10: =IFERROR(VLOOKUP("CECINAS DE LOMO C/YUCA",J:K,2,FALSE),"0")+IFERROR(VLOOKUP("PIQUEO DOÑA FRESIA",J:K,2,FALSE)/2,0) -> 0.5 | H10: =D10-E10-F10-G10 -> 4 | J10: CABRITO C/ARROZ FRIJOL Y YUCA | K10: 20
A11: ADOBO | B11: 7 | D11: =B11+C11 -> 7 | E11: =IFERROR(VLOOKUP("CARNE DE CERDO ADOBADA",J:K,2,FALSE),0) -> 5 | H11: =D11-E11-F11-G11 -> 2 | J11: CABRITO DESHUESADO | K11: 27
A12: SANCOCHADO | D12: =B12+C12 -> 0 | E12: =IFERROR(VLOOKUP("SANCOCHADO 450g.",J:K,2,FALSE),0) -> 0 | H12: =D12-E12-F12-G12 -> 0 | J12: CARNE DE CERDO ADOBADA | K12: 5
A13: SHAMBAR | D13: =B13+C13 -> 0 | E13: =IFERROR(VLOOKUP(A13,J:K,2,FALSE),0) -> 0 | H13: =D13-E13-F13-G13 -> 0 | J13: CAUSA DE POLLO | K13: 2
A14: CALDO DE GALLINA | B14: 2 | C14: 3 | D14: =B14+C14 -> 5 | E14: =IFERROR(VLOOKUP(A14,J:K,2,FALSE),0) -> 3 | H14: =D14-E14-F14-G14 -> 2 | J14: CEVICHE DE LENGUADO | K14: 10
A15: GUISOS | J15: CORVINA GUISADA C/E CHOCLO | K15: 5
A16: ASADO | B16: 2 | C16: 30 | D16: =B16+C16 -> 32 | E16: =IFERROR(VLOOKUP("ASADO DE RES CON ARROZ Y PURE",J:K,2,FALSE),0)+IFERROR(VLOOKUP("FETUCCINI AL P.C/ ASADO DE RES",J:K,2,FALSE),"0")+IFERROR(VLOOKUP("FETUCCINI A LO ALFR.C/ ASADO DE RES",J:K,2,FALSE),"0")+IFERROR(VLOOKUP("FETUCCINI A LA H.C/ ASADO DE RES",J:K,2,FALSE),"0")+IFERROR(VLOOKUP("SANDWICH DE ASADO DE RES",J:K,2,FALSE),0)+IFERROR(VLOOKUP("RISOTTO A LA H. C/ASADO",J:K,2,FALSE),0)+IFERROR(VLOOKUP("RISOTTO AL PESTO C/ASADO",J:K,2,FALSE),0)+IFERROR(VLOOKUP("TACU TACU C/ ASADO DE RES",J:K,2,FALSE),0) -> 12 | H16: =D16-E16-F16-G16 -> 20 | J16: ENSALADA MIXTA PERSONAL | K16: 1
A17: CUY | B17: 1 | C17: 10 | D17: =B17+C17 -> 11 | E17: =IFERROR(VLOOKUP("AJIACO DE CUY(1/2 CUY) C/ARROZ",J:K,2,FALSE),"0") -> 5 | H17: =D17-E17-F17-G17 -> 6 | J17: FETUCCINI AL P.C/ MILANESA | K17: 1
A18: ALBONDIGA | B18: 6 | C18: 3 | D18: =B18+C18 -> 9 | E18: =IFERROR(VLOOKUP("ALBONDIGA CON ARROZ",J:K,2,FALSE),"0") -> 9 | H18: =D18-E18-F18-G18 -> 0 | J18: FILETE DE POLLO A LA PLANCHA | K18: 9
A19: ARROZ C. PATO | B19: 0 | C19: 20 | D19: =B19+C19 -> 20 | E19: =IFERROR(VLOOKUP("ARROZ C/PATO DESHUESADO", J:K, 2, FALSE)*2, 0)+IFERROR(VLOOKUP("ARROZ C/PATO",J:K,2,FALSE),"0") -> 20 | H19: =D19-E19-F19-G19 -> 0 | J19: LENGUADO A LA MEUNIERE | K19: 1
A20: CABRITO NORMAL | B20: 40 | C20: 47 | D20: =B20+C20 -> 87 | E20: =IFERROR(VLOOKUP("CABRITO C/ TACU TACU",J:K,2,FALSE),"0")+IFERROR(VLOOKUP("CABRITO C/ARROZ FRIJOL Y YUCA",J:K,2,FALSE),"0")+IFERROR(VLOOKUP("PRESA DE CABRITO",J:K,2,FALSE),"0")+IFERROR(VLOOKUP("CABRITO DESHUESADO",J:K,2,FALSE)*2,"0")+IFERROR(VLOOKUP("TACU TACU C/ CABRITO DESHUESADO",J:K,2,FALSE)*2,"0")+IFERROR(VLOOKUP("PIQUEO DOÑA FRESIA",J:K,2,FALSE)*2,"0") -> 82 | H20: =D20-E20-F20-G20 -> 5 | J20: LENGUADO A LA PLANCHA CON ARROZ | K20: 11
A21: CABRITO DESHUESADO | D21: =B21+C21 -> 0 | J21: LENGUADO A LO MACHO CON YUCA | K21: 1
A22: PATO ESTOFADO | B22: 15 | C22: 18 | D22: =B22+C22 -> 33 | E22: =IFERROR(VLOOKUP("PATO ESTOFADO C/ARROZ Y FRIJOL",J:K,2,FALSE),0)+IFERROR(VLOOKUP("PATO ESTOFADO DESHUESADO",J:K,2,FALSE)*2,0)+IFERROR(VLOOKUP("TACU TACU C/ PATO ESTOF. DESHUESADO",J:K,2,FALSE)*2,0)+IFERROR(VLOOKUP("PIQUEO DOÑA FRESIA",J:K,2,FALSE)*2,0)+IFERROR(VLOOKUP("PATO ESTOFADO CON TACU TACU",J:K,2,FALSE),0) -> 26 | H22: =D22-E22-F22-G22 -> 7 | I22: SE PASO 10 PRESAS PARA ARROZ CON PATO | J22: LOMO A LAS 3 PIMIENTAS | K22: 1
A23: PEPIAN | B23: 3 | C23: 6 | D23: =B23+C23 -> 9 | E23: =IFERROR(VLOOKUP("PEPIAN DE PAVO",J:K,2,FALSE),"0")+IFERROR(VLOOKUP("PRESA DE PAVA",J:K,2,FALSE),0)+IFERROR(VLOOKUP("SANDWICH DE PAVO",J:K,2,FALSE),0) -> 9 | H23: =D23-E23-F23-G23 -> 0 | J23: LOMO SALTADO A NUESTRO ESTILO | K23: 1
A24: CORVINA GUISADA | B24: 2 | C24: 5 | D24: =B24+C24 -> 7 | E24: =IFERROR(VLOOKUP("CORVINA GUISADA C/E CHOCLO",J:K,2,FALSE),"0") -> 5 | H24: =D24-E24-F24-G24 -> 2 | J24: LOMO FINO EN SALSA D CHAMPIÑONES | K24: 4
A25: FRITURAS | J25: LOMO SALTADO C/ARROZ | K25: 9
A26: LOMO SALTADO | B26: 6 | C26: 10 | D26: =B26+C26 -> 16 | E26: =IFERROR(VLOOKUP("LOMO SALTADO C/ARROZ",J:K,2,FALSE),0)+IFERROR(VLOOKUP("TACU TACU C/ LOMO SALTADO",J:K,2,FALSE),0)+IFERROR(VLOOKUP("LOMO SALTADO A LO POBRE",J:K,2,FALSE),0)++IFERROR(VLOOKUP("FETUCCINI AL P.C/ LOMO SALTADO",J:K,2,FALSE),"0")+IFERROR(VLOOKUP("FETUCCINI A LO ALFR.C/ LOMO SALTADO",J:K,2,FALSE),"0")+IFERROR(VLOOKUP("FETUCCINI A LA H.C/ LOMO SALTADO",J:K,2,FALSE),"0")+IFERROR(VLOOKUP("RISOTTO A LA H. C/ LOMO SALTADO",J:K,2,FALSE),0)+IFERROR(VLOOKUP("RISOTTO PESTO C/LOMO SALTADO",J:K,2,FALSE),0)+IFERROR(VLOOKUP("CAUSA DE LOMO FINO SALTADO",J:K,2,FALSE)/2,0)+IFERROR(VLOOKUP("LOMO SALTADO A NUESTRO ESTILO",J:K,2,FALSE),0)+IFERROR(VLOOKUP("SANDWICH DE LOMO FINO SALTADO",J:K,2,FALSE)/2,0)+IFERROR(VLOOKUP("LOMO SALTADO C/ ARROZ Y FRIJOL",J:K,2,FALSE),0)+IFERROR(VLOOKUP("SALTADO MAR Y TIERRA ",$J:$K,2,FALSE)/2,0)+IFERROR(VLOOKUP("LOMO EN NUESTRO ESTILO",$J:$K,2,FALSE),0) -> 14 | H26: =D26-E26-F26-G26 -> 2 | J26: MOLLEJITAS GUISADAS | K26: 2
A27: FILETE DE POLLO CARTA | B27: 4 | C27: 14 | D27: =B27+C27 -> 18 | E27: =IFERROR(VLOOKUP("FILETE DE POLLO A LA PLANCHA",J:K,2,FALSE),"0")+IFERROR(VLOOKUP("FETUCCINI A LO ALFR.C/ FILETE DE POLLO",J:K,2,FALSE),"0")+IFERROR(VLOOKUP("FETUCCINI A LA H.C/ FILETE DE POLLO",J:K,2,FALSE),"0")+IFERROR(VLOOKUP("FETUCCINI AL P.C/ FILETE DE POLLO",J:K,2,FALSE),"0")+IFERROR(VLOOKUP("PIQUEO PERUANISIMO",J:K,2,FALSE)*2,0)+IFERROR(VLOOKUP("DIETA DE POLLO",J:K,2,FALSE),0)+IFERROR(VLOOKUP("RISOTTO PESTO C/FILETE DE POLLO",J:K,2,FALSE),0)+IFERROR(VLOOKUP("POLLO SALTADO C/ ARROZ Y PAPAS FRITAS",J:K,2,FALSE),0)+IFERROR(VLOOKUP("PRESA DE FILETE DE POLLO",J:K,2,FALSE),0)+IFERROR(VLOOKUP("SALTADO MAR Y TIERRA ",J:K,2,FALSE)/2,0)+IFERROR(VLOOKUP("CAUSA DE POLLO ",J:K,2,FALSE),0)+IFERROR(VLOOKUP("SANDWICH DE POLLO ",J:K,2,FALSE),0) -> 11 | H27: =D27-E27-F27-G27 -> 7 | J27: PAPA RELLENA | K27: 1
A28: MILANESA CARTA | B28: 7 | C28: 5 | D28: =B28+C28 -> 12 | E28: =IFERROR(VLOOKUP("MILANESA DE POLLO",J:K,2,FALSE),"0")+IFERROR(VLOOKUP("FETUCCINI AL P.C/ MILANESA",J:K,2,FALSE),"0")+IFERROR(VLOOKUP("FETUCCINI A LO ALFR.C/ MILANESA",J:K,2,FALSE),"0")+IFERROR(VLOOKUP("FETUCCINI A LA H.C/ MILANESA",J:K,2,FALSE),"0")+IFERROR(VLOOKUP("MILANESA DE POLLO A LO POBRE",J:K,2,FALSE),"0")+IFERROR(VLOOKUP("RISOTTO PESTO C/MILANESA",J:K,2,FALSE),0)+IFERROR(VLOOKUP("TACU TACU C/ MILANESA",J:K,2,FALSE),0)+IFERROR(VLOOKUP("RISOTTO A LA H. C/MILANESA DE POLLO",J:K,2,FALSE),0) -> 7 | H28: =D28-E28-F28-G28 -> 5 | J28: PATITA EN FIAMBRE | K28: 8
A29: BISTEC CARTA | B29: 6 | C29: 2 | D29: =B29+C29 -> 8 | E29: =IFERROR(VLOOKUP("TACU TACU C/ BISTEC A LO POBRE",J:K,2,FALSE),0)+IFERROR(VLOOKUP("BISTEC DE LOMO FINO A LO POBRE",J:K,2,FALSE),0)+IFERROR(VLOOKUP("FETUCCINI AL P.C/ BISTEC DE LOMO 250 G",J:K,2,FALSE),"0")+IFERROR(VLOOKUP("FETUCCINI A LO ALFR.C/ BISTEC DE LOMO 250 G",J:K,2,FALSE),"0")+IFERROR(VLOOKUP("FETUCCINI A LA H.C/ BISTEC DE LOMO 250 G",J:K,2,FALSE),"0")+IFERROR(VLOOKUP("FETUCCINI AL P.C/ BISTEC DE LOMO APANADO",J:K,2,FALSE),"0")+IFERROR(VLOOKUP("FETUCCINI A LO ALFR.C/ BISTEC DE LOMO APANADO",J:K,2,FALSE),"0")+IFERROR(VLOOKUP("FETUCCINI A LA H.C/ BISTEC DE LOMO APANADO",J:K,2,FALSE),"0")+IFERROR(VLOOKUP("RISOTTO A LA H. BISTEC DE LOMO 250 G",J:K,2,FALSE),0)+IFERROR(VLOOKUP("RISOTTO PESTO C/BISTEC DE LOMO 250 G",J:K,2,FALSE),0)+IFERROR(VLOOKUP("BISTEC DE LOMO FINO A LA PLANCHA",J:K,2,FALSE),0)+IFERROR(VLOOKUP("LOMO A LAS 3 PIMIENTAS",J:K,2,FALSE),0)+IFERROR(VLOOKUP("LOMO FINO EN SALSA D CHAMPIÑONES",J:K,2,FALSE),0)+IFERROR(VLOOKUP("BISTEC DE LOMO FINO APANADO",J:K,2,FALSE),0)+IFERROR(VLOOKUP("TACU TACU C/LOMO FINO EN SALSA DE LANGOSTINOS",J:K,2,FALSE),0) -> 6 | H29: =D29-E29-F29-G29 -> 2 | J29: PATO ESTOFADO C/ARROZ Y FRIJOL | K29: 4
A30: CHICHARRON DE POLLO | D30: =B30+C30 -> 0 | E30: =IFERROR(VLOOKUP("CHICHARRON DE POLLO C/ PAPAS FRITAS",J:K,2,FALSE),0)+IFERROR(VLOOKUP("1/2 PORC. CHICHARRON DE POLLO",J:K,2,FALSE),0) -> 0 | H30: =D30-E30-F30-G30 -> 0 | J30: PATO ESTOFADO DESHUESADO | K30: 9
A31: PESCADOS Y MARISCOS | D31: =B31+C31 -> 0 | H31: =D31-E31-F31-G31 -> 0 | J31: PEPIAN DE PAVO | K31: 9
A32: LENGUADO | C32: 40 | D32: =B32+C32 -> 40 | E32: =IFERROR(VLOOKUP("CEVICHE MIXTO DE MARISCOS",J:K,2,FALSE),0)+IFERROR(VLOOKUP("CEVICHE DE LENGUADO",J:K,2,FALSE),0)+IFERROR(VLOOKUP("LENGUADO A LA PLANCHA CON ARROZ",J:K,2,FALSE),0)+IFERROR(VLOOKUP("LENGUADO A LO MACHO CON YUCA",J:K,2,FALSE),0)+IFERROR(VLOOKUP("LENGUADO APANADA C/ARROZ Y FRIJOL",J:K,2,FALSE),0)+IFERROR(VLOOKUP("LENGUADO ESCABECHADO C/ARROZ Y CAMOTE",J:K,2,FALSE),0)+IFERROR(VLOOKUP("TACU TACU C/ LENGUADO EN SALSA DE LANGOSTINOS",J:K,2,FALSE),0)+IFERROR(VLOOKUP("TACU TACU C/LENGUADO EN SALSA DE MARISCOS",J:K,2,FALSE),0)+IFERROR(VLOOKUP("TIRADITO DE LENGUADO A LAS DOS CREMAS",J:K,2,FALSE),0)+IFERROR(VLOOKUP("TIRADITO DE LENGUADO O SIMILAR",J:K,2,FALSE),0)+IFERROR(VLOOKUP("CHICHARRON DE LENGUADO",J:K,2,FALSE),0)+IFERROR(VLOOKUP("JALEA DE LENGUADO O SIMILAR",J:K,2,FALSE),0)+IFERROR(VLOOKUP("LENGUADO O CORVINA FRITA C/ARROZ Y YUCA",J:K,FALSE),0)+IFERROR(VLOOKUP("LENGUADO O CORVINA FRITA EN S/MARISCOS",J:K,2,FALSE),0)+IFERROR(VLOOKUP("LENGUADO O SIMILAR AL AJO C/ARROZ",J:K,2,FALSE),0)+IFERROR(VLOOKUP("LENGUADO A LA MEUNIERE",J:K,2,FALSE),0)+IFERROR(VLOOKUP("TACU TACU C/ LENGUADO A LO MACHO",J:K,2,FALSE),0)+IFERROR(VLOOKUP("CHICHARRON MIXTO DE MARISCOS",J:K,2,FALSE),0)+IFERROR(VLOOKUP("FUENTE DE CEVICHE DE CORVINA O LENGUADO",J:K,2,FALSE)*2,0)+IFERROR(VLOOKUP("CAUSA DE LA CASA ",J:K,2,FALSE),0)+IFERROR(VLOOKUP("TACU TACU C/ LENGUDO EN SALSA DE LANGOSTINOS",J:K,2,FALSE),0) -> 27 | H32: =D32-E32-F32-G32 -> 13 | J32: PICARONES C/ MIEL DE HIGO | K32: 1
A33: CORVINA | C33: 5 | D33: =B33+C33 -> 5 | E33: =IFERROR(VLOOKUP("CORVINA SUDADA",J:K,2,FALSE),0)+IFERROR(VLOOKUP("CHUPE DE CORVINA",J:K,2,FALSE),0) -> 3 | H33: =D33-E33-F33-G33 -> 2 | J33: PIQUEO DOÑA FRESIA | K33: 1
A34: PULPO | C34: 5 | D34: =B34+C34 -> 5 | E34: =IFERROR(VLOOKUP("PULPO ANTICUCHERO 250G",J:K,2,FALSE),0)+IFERROR(VLOOKUP("PULPO AL OLIVO 200G",J:K,2,FALSE),0)+IFERROR(VLOOKUP("CEVICHE DE PULPO",J:K,2,FALSE),0)+IFERROR(VLOOKUP("CAUSA DE PULPO AL OLIVO",J:K,2,FALSE),0)+IFERROR(VLOOKUP("CEVICHE DE PULPO",J:K,2,FALSE)*2,0)+IFERROR(VLOOKUP("TRES CAUSAS UNA PARRILLA",J:K,2,FALSE)/2,0) -> 1 | H34: =D34-E34-F34-G34 -> 4 | J34: PULPO ANTICUCHERO 250G | K34: 1
A35: CAMARON | D35: =B35+C35 -> 0 | E35: =IFERROR(VLOOKUP("CHUPE DE CAMARORES",J:K,2,FALSE),0)+IFERROR(VLOOKUP("CAMARONES AL AJO",J:K,2,FALSE),0)+IFERROR(VLOOKUP("CEVICHE DE CAMARONES",J:K,2,FALSE),0)+IFERROR(VLOOKUP("ARROZ CON CAMARONES",J:K,2,FALSE),0)+IFERROR(VLOOKUP("CAUSA DE CAMARONES",J:K,2,FALSE),0) -> 0 | H35: =D35-E35-F35-G35 -> 0 | J35: SANGRECITA C/YUCA | K35: 16
A36: MIXTURA | C36: 10 | D36: =B36+C36 -> 10 | E36: =IFERROR(VLOOKUP("PIQUEO FRUTOS DEL MAR",J:K,2,FALSE)*2,0)+IFERROR(VLOOKUP("CEVICHE MIXTO DE MARISCOS",J:K,2,FALSE),0)+IFERROR(VLOOKUP("ARROZ C/MARISCOS",J:K,2,FALSE),0)+IFERROR(VLOOKUP("TORTILLA DE MARISCOS C/ ARROZ",J:K,2,FALSE),0)+IFERROR(VLOOKUP("CHAUFA DE MARISCOS",J:K,2,FALSE),0)+IFERROR(VLOOKUP("PARIHUELA DE MARISCOS",J:K,2,FALSE),0)+IFERROR(VLOOKUP("PICANTE DE MARISCOS",J:K,2,FALSE),0)+IFERROR(VLOOKUP("TACU TACU EN SALSA DE MARISCOS",J:K,2,FALSE),0)+IFERROR(VLOOKUP("TRÍO DE CAUSAS",J:K,2,FALSE),0)+IFERROR(VLOOKUP("CHICHARRON MIXTO DE MARISCOS",J:K,2,FALSE),0)+IFERROR(VLOOKUP("LENGUADO O CORVINA FRITA EN S/MARISCOS",J:K,2,FALSE),0)+IFERROR(VLOOKUP("TACU TACU C/LENGUADO EN SALSA DE MARISCOS",J:K,2,FALSE),0)+IFERROR(VLOOKUP("RISOTTO FRUTOS DEL MAR",J:K,2,FALSE),0)+IFERROR(VLOOKUP("TRES CAUSAS UNA PARRILLA",J:K,2,FALSE)/2,0) -> 6 | H36: =D36-$E$36-F36-G36 -> 4 | J36: TACU TACU C/ CABRITO DESHUESADO | K36: 3
A37: TOLLO | C37: 10 | D37: =B37+C37 -> 10 | E37: =IFERROR(VLOOKUP("PIQUEO FRUTOS DEL MAR",J:K,2,FALSE)*2,0)+IFERROR(VLOOKUP("CHICHARRON PESCA DEL DIA",J:K,2,FALSE),0)+IFERROR(VLOOKUP("CEVICHE PESCA DEL DIA",J:K,2,FALSE),0)+IFERROR(VLOOKUP("LECHE DE TIGRE",J:K,2,FALSE),0)+IFERROR(VLOOKUP("1/2 LECHE DE TIGRE",J:K,2,FALSE)/2,0)+IFERROR(VLOOKUP("TRILOGIA DE LECHES DE TIGRE ",J:K,2,FALSE),0)+IFERROR(VLOOKUP("CAUSA EN SALSA ACEVICHADA ",J:K,2,FALSE),0)+IFERROR(VLOOKUP("CAUSA DE LA CASA",J:K,2,FALSE),0) -> 3 | H37: =D37-$E$36-F37-G37 -> 4 | J37: TACU TACU C/ LOMO SALTADO | K37: 4
A38: LANGOSTINO | C38: 10 | D38: =B38+C38 -> 10 | E38: =IFERROR(VLOOKUP("LANGOSTINO THAI",J:K,2,FALSE),0)+IFERROR(VLOOKUP("LANGOSTINOS CROCANTES CON PALTA BRACEADA",J:K,2,FALSE),0)+IFERROR(VLOOKUP("ARROZ C/LANGOSTINOS",J:K,2,FALSE),0)+IFERROR(VLOOKUP("SALTADO MAR Y TIERRA",J:K,2,FALSE)/2,0)+IFERROR(VLOOKUP("CAUSA DE LANGOSTINOS",J:K,2,FALSE),0)+IFERROR(VLOOKUP("TACU TACU C/ LENGUADO EN SALSA DE LANGOSTINOS",J:K,2,FALSE),0)+IFERROR(VLOOKUP("TACU TACU C/LOMO FINO EN SALSA DE LANGOSTINOS",J:K,2,FALSE),0) -> 0.5 | H38: =D38-$E$36-F38-G38 -> 4 | J38: TRIO DE CAUSAS | K38: 4
J39: CECINA | K39: 6
J40: LECHE DE TIGRE | K40: 1
J41: MILANESA DE POLLO | K41: 5
...

Sheet 22.09.25
A1: KARDEX COCINA - FECHA 22.09.25
A2: ENTRADAS | B2: SALDO INICIAL | C2: INGRESOS | D2: TOTAL | E2: VENTA | F2: MENU | G2: MERMA/ VARIOS | H2: SALDO FINAL | I2: OBSERVACION
A3: TAMALES | B3: ='21.09.25'!H3 -> 0 | C3: 5 | D3: =B3+C3 -> 5 | E3: =IFERROR(VLOOKUP("TAMAL DE LA CASA CON ZARZA CRIOLLAL",J:K,2,FALSE),"0") -> 0 | H3: =D3-E3-F3-G3 -> 5 | J3: AJI DE GALLINA | K3: 1
A4: HUMITAS | B4: ='21.09.25'!H4 -> 0 | D4: =B4+C4 -> 0 | E4: =IFERROR(VLOOKUP("HUMITA DOÑA FRESIA C/AJI DE GALLINA",J:K,2,FALSE),"0") -> 0 | H4: =D4-E4-F4-G4 -> 0 | J4: BISTEC DE LOMO FINO A LO POBRE | K4: 3
A5: PAPA RELLENA | B5: ='21.09.25'!H5 -> 7 | D5: =B5+C5 -> 7 | E5: =IFERROR(VLOOKUP(A$5,J:K,2,FALSE),0)+IFERROR(VLOOKUP("PIQUEO PERUANISIMO",J:K,2,FALSE),0) -> 2 | G5: 4 | H5: =D5-E5-F5-G5 -> 1 | I5: MAL ELABORADAS | J5: CABRITO C/ARROZ FRIJOL Y YUCA | K5: 10
A6: SANGRECITA | B6: ='21.09.25'!H6 -> 0 | C6: 7 | D6: =B6+C6 -> 7 | E6: =IFERROR(VLOOKUP("SANGRECITA C/YUCA",J:K,2,FALSE),"0") -> 3 | H6: =D6-E6-F6-G6 -> 4 | J6: CABRITO DESHUESADO | K6: 3
A7: AJI DE GALLINA | B7: ='21.09.25'!H7 -> 6 | C7: 4 | D7: =B7+C7 -> 10 | E7: =IFERROR(VLOOKUP("HUMITA DOÑA FRESIA C/AJI DE GALLINA", J:K,2, FALSE)/2, 0) + IFERROR(VLOOKUP("AJI DE GALLINA",J:K,2, FALSE), 0) -> 1 | H7: =D7-E7-F7-G7 -> 9 | J7: CAUSA DE LOMO FINO SALTADO | K7: 1
A8: MOLLEJITA | B8: ='21.09.25'!H8 -> 2 | C8: 6 | D8: =B8+C8 -> 8 | E8: =IFERROR(VLOOKUP("MOLLEJITAS GUISADAS",J:K,2,FALSE),"0")+IFERROR(VLOOKUP("PIQUEO DOÑA FRESIA",J:K,2,FALSE),0) -> 0 | H8: =D8-E8-F8-G8 -> 8 | J8: CECINAS DE LOMO C/YUCA | K8: 3
A9: PATITA | B9: ='21.09.25'!H9 -> 0 | C9: 11 | D9: =B9+C9 -> 11 | E9: =IFERROR(VLOOKUP("1/2 PATITA EN FIAMBRE",J:K,2, FALSE)/2, 0) + IFERROR(VLOOKUP("PATITA EN FIAMBRE",J:K, 2, FALSE), 0) -> 3.5 | H9: =D9-E9-F9-G9 -> 7.5 | J9: FETUCCINI A LA H.C/ LOMO SALTADO | K9: 2
A10: CECINA | B10: ='21.09.25'!H10 -> 4 | D10: =B10+C10 -> 4 | E10: =IFERROR(VLOOKUP("CECINAS DE LOMO C/YUCA",J:K,2,FALSE),"0")+IFERROR(VLOOKUP("PIQUEO DOÑA FRESIA",J:K,2,FALSE)/2,0) -> 3 | H10: =D10-E10-F10-G10 -> 1 | J10: FILETE DE POLLO A LA PLANCHA | K10: 2
A11: ADOBO | B11: ='21.09.25'!H11 -> 2 | C11: 5 | D11: =B11+C11 -> 7 | E11: =IFERROR(VLOOKUP("CARNE DE CERDO ADOBADA",J:K,2,FALSE),0) -> 0 | H11: =D11-E11-F11-G11 -> 7 | J11: LOMO A LAS 3 PIMIENTAS | K11: 2
A12: SANCOCHADO | B12: ='21.09.25'!H12 -> 0 | D12: =B12+C12 -> 0 | E12: =IFERROR(VLOOKUP("SANCOCHADO 450g.",J:K,2,FALSE),0) -> 0 | H12: =D12-E12-F12-G12 -> 0 | J12: LOMO SALTADO C/ARROZ | K12: 5
A13: SHAMBAR | B13: ='21.09.25'!H13 -> 0 | C13: 25 | D13: =B13+C13 -> 25 | E13: =IFERROR(VLOOKUP(A13,J:K,2,FALSE),0) -> 22 | H13: =D13-E13-F13-G13 -> 3 | J13: MILANESA DE POLLO | K13: 2
A14: CALDO DE GALLINA | B14: ='21.09.25'!H14 -> 2 | D14: =B14+C14 -> 2 | E14: =IFERROR(VLOOKUP(A14,J:K,2,FALSE),0) -> 0 | G14: 2 | H14: =D14-E14-F14-G14 -> 0 | I14: MENU | J14: PAPA RELLENA | K14: 2
A15: GUISOS | J15: PATO ESTOFADO DESHUESADO | K15: 4
A16: ASADO | B16: ='21.09.25'!H16 -> 20 | C16: 48 | D16: =B16+C16 -> 68 | E16: =IFERROR(VLOOKUP("ASADO DE RES CON ARROZ Y PURE",J:K,2,FALSE),0)+IFERROR(VLOOKUP("FETUCCINI AL P.C/ ASADO DE RES",J:K,2,FALSE),"0")+IFERROR(VLOOKUP("FETUCCINI A LO ALFR.C/ ASADO DE RES",J:K,2,FALSE),"0")+IFERROR(VLOOKUP("FETUCCINI A LA H.C/ ASADO DE RES",J:K,2,FALSE),"0")+IFERROR(VLOOKUP("SANDWICH DE ASADO DE RES",J:K,2,FALSE),0)+IFERROR(VLOOKUP("RISOTTO A LA H. C/ASADO",J:K,2,FALSE),0)+IFERROR(VLOOKUP("RISOTTO AL PESTO C/ASADO",J:K,2,FALSE),0)+IFERROR(VLOOKUP("TACU TACU C/ ASADO DE RES",J:K,2,FALSE),0) -> 1 | G16: 47 | H16: =D16-E16-F16-G16 -> 20 | I16: RESESERVA | J16: PORCIÓN DE FETUCCINI A LA HUANCAÍNA | K16: 1
A17: CUY | B17: ='21.09.25'!H17 -> 6 | D17: =B17+C17 -> 6 | E17: =IFERROR(VLOOKUP("AJIACO DE CUY(1/2 CUY) C/ARROZ",J:K,2,FALSE),"0") -> 1 | H17: =D17-E17-F17-G17 -> 5 | J17: SANGRECITA C/YUCA | K17: 3
A18: ALBONDIGA | B18: ='21.09.25'!H18 -> 0 | C18: 6 | D18: =B18+C18 -> 6 | E18: =IFERROR(VLOOKUP("ALBONDIGA CON ARROZ",J:K,2,FALSE),"0") -> 2 | H18: =D18-E18-F18-G18 -> 4 | J18: SHAMBAR | K18: 22
A19: ARROZ C. PATO | B19: ='21.09.25'!H19 -> 0 | C19: 9 | D19: =B19+C19 -> 9 | E19: =IFERROR(VLOOKUP("ARROZ C/PATO DESHUESADO", J:K, 2, FALSE)*2, 0)+IFERROR(VLOOKUP("ARROZ C/PATO",J:K,2,FALSE),"0") -> 4 | G19: 5 | H19: =D19-E19-F19-G19 -> 0 | I19: PASA PARA PATO ESTOFADO | J19: AJIACO DE CUY(1/2 CUY) C/ARROZ | K19: 1
A20: CABRITO NORMAL | B20: ='21.09.25'!H20 -> 5 | C20: 51 | D20: =B20+C20 -> 56 | E20: =IFERROR(VLOOKUP("CABRITO C/ TACU TACU",J:K,2,FALSE),"0")+IFERROR(VLOOKUP("CABRITO C/ARROZ FRIJOL Y YUCA",J:K,2,FALSE),"0")+IFERROR(VLOOKUP("PRESA DE CABRITO",J:K,2,FALSE),"0")+IFERROR(VLOOKUP("CABRITO DESHUESADO",J:K,2,FALSE)*2,"0")+IFERROR(VLOOKUP("TACU TACU C/ CABRITO DESHUESADO",J:K,2,FALSE)*2,"0")+IFERROR(VLOOKUP("PIQUEO DOÑA FRESIA",J:K,2,FALSE)*2,"0") -> 16 | H20: =D20-E20-F20-G20 -> 40 | J20: ALBONDIGA CON ARROZ | K20: 2
A21: CABRITO DESHUESADO | B21: ='21.09.25'!H21 | D21: =B21+C21 -> 0 | J21: TIRADITO DE LENGUADO A LAS DOS CREMAS | K21: 1
A22: PATO ESTOFADO | B22: ='21.09.25'!H22 -> 7 | C22: 29 | D22: =B22+C22 -> 36 | E22: =IFERROR(VLOOKUP("PATO ESTOFADO C/ARROZ Y FRIJOL",J:K,2,FALSE),0)+IFERROR(VLOOKUP("PATO ESTOFADO DESHUESADO",J:K,2,FALSE)*2,0)+IFERROR(VLOOKUP("TACU TACU C/ PATO ESTOF. DESHUESADO",J:K,2,FALSE)*2,0)+IFERROR(VLOOKUP("PIQUEO DOÑA FRESIA",J:K,2,FALSE)*2,0)+IFERROR(VLOOKUP("PATO ESTOFADO CON TACU TACU",J:K,2,FALSE),0) -> 8 | H22: =D22-E22-F22-G22 -> 28 | I22: SE PASO 10 PRESAS PARA ARROZ CON PATO | J22: CAUSA EN SALSA ACEVICHADA | K22: 1
A23: PEPIAN | B23: ='21.09.25'!H23 -> 0 | D23: =B23+C23 -> 0 | E23: =IFERROR(VLOOKUP("PEPIAN DE PAVO",J:K,2,FALSE),"0")+IFERROR(VLOOKUP("PRESA DE PAVA",J:K,2,FALSE),0)+IFERROR(VLOOKUP("SANDWICH DE PAVO",J:K,2,FALSE),0) -> 0 | H23: =D23-E23-F23-G23 -> 0 | J23: CEVICHE DE LENGUADO | K23: 4
A24: CORVINA GUISADA | B24: ='21.09.25'!H24 -> 2 | C24: 3 | D24: =B24+C24 -> 5 | E24: =IFERROR(VLOOKUP("CORVINA GUISADA C/E CHOCLO",J:K,2,FALSE),"0") -> 0 | H24: =D24-E24-F24-G24 -> 5 | J24: LENGUADO O CORVINA FRITA C/ARROZ Y YUCA | K24: 1
A25: FRITURAS | J25: PATITA EN FIAMBRE | K25: 2
A26: LOMO SALTADO | B26: ='21.09.25'!H26 -> 2 | C26: 5.5 | D26: =B26+C26 -> 7.5 | E26: =IFERROR(VLOOKUP("LOMO SALTADO C/ARROZ",J:K,2,FALSE),0)+IFERROR(VLOOKUP("TACU TACU C/ LOMO SALTADO",J:K,2,FALSE),0)+IFERROR(VLOOKUP("LOMO SALTADO A LO POBRE",J:K,2,FALSE),0)++IFERROR(VLOOKUP("FETUCCINI AL P.C/ LOMO SALTADO",J:K,2,FALSE),"0")+IFERROR(VLOOKUP("FETUCCINI A LO ALFR.C/ LOMO SALTADO",J:K,2,FALSE),"0")+IFERROR(VLOOKUP("FETUCCINI A LA H.C/ LOMO SALTADO",J:K,2,FALSE),"0")+IFERROR(VLOOKUP("RISOTTO A LA H. C/ LOMO SALTADO",J:K,2,FALSE),0)+IFERROR(VLOOKUP("RISOTTO PESTO C/LOMO SALTADO",J:K,2,FALSE),0)+IFERROR(VLOOKUP("CAUSA DE LOMO FINO SALTADO",J:K,2,FALSE)/2,0)+IFERROR(VLOOKUP("LOMO SALTADO A NUESTRO ESTILO",J:K,2,FALSE),0)+IFERROR(VLOOKUP("SANDWICH DE LOMO FINO SALTADO",J:K,2,FALSE)/2,0)+IFERROR(VLOOKUP("LOMO SALTADO C/ ARROZ Y FRIJOL",J:K,2,FALSE),0)+IFERROR(VLOOKUP("SALTADO MAR Y TIERRA ",$J:$K,2,FALSE)/2,0)+IFERROR(VLOOKUP("LOMO EN NUESTRO ESTILO",$J:$K,2,FALSE),0) -> 7.5 | H26: =D26-E26-F26-G26 -> 0 | J26: CHICHARRON DE LANGOSTINOS | K26: 1
A27: FILETE DE POLLO CARTA | B27: ='21.09.25'!H27 -> 7 | D27: =B27+C27 -> 7 | E27: =IFERROR(VLOOKUP("FILETE DE POLLO A LA PLANCHA",J:K,2,FALSE),"0")+IFERROR(VLOOKUP("FETUCCINI A LO ALFR.C/ FILETE DE POLLO",J:K,2,FALSE),"0")+IFERROR(VLOOKUP("FETUCCINI A LA H.C/ FILETE DE POLLO",J:K,2,FALSE),"0")+IFERROR(VLOOKUP("FETUCCINI AL P.C/ FILETE DE POLLO",J:K,2,FALSE),"0")+IFERROR(VLOOKUP("PIQUEO PERUANISIMO",J:K,2,FALSE)*2,0)+IFERROR(VLOOKUP("DIETA DE POLLO",J:K,2,FALSE),0)+IFERROR(VLOOKUP("RISOTTO PESTO C/FILETE DE POLLO",J:K,2,FALSE),0)+IFERROR(VLOOKUP("POLLO SALTADO C/ ARROZ Y PAPAS FRITAS",J:K,2,FALSE),0)+IFERROR(VLOOKUP("PRESA DE FILETE DE POLLO",J:K,2,FALSE),0)+IFERROR(VLOOKUP("SALTADO MAR Y TIERRA ",J:K,2,FALSE)/2,0)+IFERROR(VLOOKUP("CAUSA DE POLLO ",J:K,2,FALSE),0)+IFERROR(VLOOKUP("SANDWICH DE POLLO ",J:K,2,FALSE),0) -> 3 | H27: =D27-E27-F27-G27 -> 4 | J27: LENGUADO APANADO C/ARROZ Y FRIJOL | K27: 1
A28: MILANESA CARTA | B28: ='21.09.25'!H28 -> 5 | C28: 3 | D28: =B28+C28 -> 8 | E28: =IFERROR(VLOOKUP("MILANESA DE POLLO",J:K,2,FALSE),"0")+IFERROR(VLOOKUP("FETUCCINI AL P.C/ MILANESA",J:K,2,FALSE),"0")+IFERROR(VLOOKUP("FETUCCINI A LO ALFR.C/ MILANESA",J:K,2,FALSE),"0")+IFERROR(VLOOKUP("FETUCCINI A LA H.C/ MILANESA",J:K,2,FALSE),"0")+IFERROR(VLOOKUP("MILANESA DE POLLO A LO POBRE",J:K,2,FALSE),"0")+IFERROR(VLOOKUP("RISOTTO PESTO C/MILANESA",J:K,2,FALSE),0)+IFERROR(VLOOKUP("TACU TACU C/ MILANESA",J:K,2,FALSE),0)+IFERROR(VLOOKUP("RISOTTO A LA H. C/MILANESA DE POLLO",J:K,2,FALSE),0) -> 2 | H28: =D28-E28-F28-G28 -> 6 | J28: 1/2 LECHE DE TIGRE | K28: 2
A29: BISTEC CARTA | B29: ='21.09.25'!H29 -> 2 | C29: 4 | D29: =B29+C29 -> 6 | E29: =IFERROR(VLOOKUP("TACU TACU C/ BISTEC A LO POBRE",J:K,2,FALSE),0)+IFERROR(VLOOKUP("BISTEC DE LOMO FINO A LO POBRE",J:K,2,FALSE),0)+IFERROR(VLOOKUP("FETUCCINI AL P.C/ BISTEC DE LOMO 250 G",J:K,2,FALSE),"0")+IFERROR(VLOOKUP("FETUCCINI A LO ALFR.C/ BISTEC DE LOMO 250 G",J:K,2,FALSE),"0")+IFERROR(VLOOKUP("FETUCCINI A LA H.C/ BISTEC DE LOMO 250 G",J:K,2,FALSE),"0")+IFERROR(VLOOKUP("FETUCCINI AL P.C/ BISTEC DE LOMO APANADO",J:K,2,FALSE),"0")+IFERROR(VLOOKUP("FETUCCINI A LO ALFR.C/ BISTEC DE LOMO APANADO",J:K,2,FALSE),"0")+IFERROR(VLOOKUP("FETUCCINI A LA H.C/ BISTEC DE LOMO APANADO",J:K,2,FALSE),"0")+IFERROR(VLOOKUP("RISOTTO A LA H. BISTEC DE LOMO 250 G",J:K,2,FALSE),0)+IFERROR(VLOOKUP("RISOTTO PESTO C/BISTEC DE LOMO 250 G",J:K,2,FALSE),0)+IFERROR(VLOOKUP("BISTEC DE LOMO FINO A LA PLANCHA",J:K,2,FALSE),0)+IFERROR(VLOOKUP("LOMO A LAS 3 PIMIENTAS",J:K,2,FALSE),0)+IFERROR(VLOOKUP("LOMO FINO EN SALSA D CHAMPIÑONES",J:K,2,FALSE),0)+IFERROR(VLOOKUP("BISTEC DE LOMO FINO APANADO",J:K,2,FALSE),0)+IFERROR(VLOOKUP("TACU TACU C/LOMO FINO EN SALSA DE LANGOSTINOS",J:K,2,FALSE),0) -> 6 | H29: =D29-E29-F29-G29 -> 0 | J29: 1/2 PATITA EN FIAMBRE | K29: 3
A30: CHICHARRON DE POLLO | B30: ='21.09.25'!H30 -> 0 | D30: =B30+C30 -> 0 | E30: =IFERROR(VLOOKUP("CHICHARRON DE POLLO C/ PAPAS FRITAS",J:K,2,FALSE),0)+IFERROR(VLOOKUP("1/2 PORC. CHICHARRON DE POLLO",J:K,2,FALSE),0) -> 0 | H30: =D30-E30-F30-G30 -> 0 | J30: ARROZ C/PATO DESHUESADO | K30: 2
A31: PESCADOS Y MARISCOS | D31: =B31+C31 -> 0 | H31: =D31-E31-F31-G31 -> 0 | J31: ASADO DE RES CON ARROZ Y PURE | K31: 1
A32: LENGUADO | B32: ='21.09.25'!H32 -> 13 | C32: 5 | D32: =B32+C32 -> 18 | E32: =IFERROR(VLOOKUP("CEVICHE MIXTO DE MARISCOS",J:K,2,FALSE),0)+IFERROR(VLOOKUP("CEVICHE DE LENGUADO",J:K,2,FALSE),0)+IFERROR(VLOOKUP("LENGUADO A LA PLANCHA CON ARROZ",J:K,2,FALSE),0)+IFERROR(VLOOKUP("LENGUADO A LO MACHO CON YUCA",J:K,2,FALSE),0)+IFERROR(VLOOKUP("LENGUADO APANADA C/ARROZ Y FRIJOL",J:K,2,FALSE),0)+IFERROR(VLOOKUP("LENGUADO ESCABECHADO C/ARROZ Y CAMOTE",J:K,2,FALSE),0)+IFERROR(VLOOKUP("TACU TACU C/ LENGUADO EN SALSA DE LANGOSTINOS",J:K,2,FALSE),0)+IFERROR(VLOOKUP("TACU TACU C/LENGUADO EN SALSA DE MARISCOS",J:K,2,FALSE),0)+IFERROR(VLOOKUP("TIRADITO DE LENGUADO A LAS DOS CREMAS",J:K,2,FALSE),0)+IFERROR(VLOOKUP("TIRADITO DE LENGUADO O SIMILAR",J:K,2,FALSE),0)+IFERROR(VLOOKUP("CHICHARRON DE LENGUADO",J:K,2,FALSE),0)+IFERROR(VLOOKUP("JALEA DE LENGUADO O SIMILAR",J:K,2,FALSE),0)+IFERROR(VLOOKUP("LENGUADO O CORVINA FRITA C/ARROZ Y YUCA",J:K,FALSE),0)+IFERROR(VLOOKUP("LENGUADO O CORVINA FRITA EN S/MARISCOS",J:K,2,FALSE),0)+IFERROR(VLOOKUP("LENGUADO O SIMILAR AL AJO C/ARROZ",J:K,2,FALSE),0)+IFERROR(VLOOKUP("LENGUADO A LA MEUNIERE",J:K,2,FALSE),0)+IFERROR(VLOOKUP("TACU TACU C/ LENGUADO A LO MACHO",J:K,2,FALSE),0)+IFERROR(VLOOKUP("CHICHARRON MIXTO DE MARISCOS",J:K,2,FALSE),0)+IFERROR(VLOOKUP("FUENTE DE CEVICHE DE CORVINA O LENGUADO",J:K,2,FALSE)*2,0)+IFERROR(VLOOKUP("CAUSA DE LA CASA ",J:K,2,FALSE),0)+IFERROR(VLOOKUP("TACU TACU C/ LENGUDO EN SALSA DE LANGOSTINOS",J:K,2,FALSE),0) -> 6 | H32: =D32-E32-F32-G32 -> 12 | J32: BISTEC DE LOMO FINO A LA PLANCHA | K32: 1
A33: CORVINA | B33: ='21.09.25'!H33 -> 2 | D33: =B33+C33 -> 2 | E33: =IFERROR(VLOOKUP("CORVINA SUDADA",J:K,2,FALSE),0)+IFERROR(VLOOKUP("CHUPE DE CORVINA",J:K,2,FALSE),0) -> 0 | H33: =D33-E33-F33-G33 -> 2 | J33: CHICHARRON MIXTO DE MARISCOS | K33: 1
A34: PULPO | B34: ='21.09.25'!H34 -> 4 | D34: =B34+C34 -> 4 | E34: =IFERROR(VLOOKUP("PULPO ANTICUCHERO 250G",J:K,2,FALSE),0)+IFERROR(VLOOKUP("PULPO AL OLIVO 200G",J:K,2,FALSE),0)+IFERROR(VLOOKUP("CEVICHE DE PULPO",J:K,2,FALSE),0)+IFERROR(VLOOKUP("CAUSA DE PULPO AL OLIVO",J:K,2,FALSE),0)+IFERROR(VLOOKUP("CEVICHE DE PULPO",J:K,2,FALSE)*2,0)+IFERROR(VLOOKUP("TRES CAUSAS UNA PARRILLA",J:K,2,FALSE)/2,0) -> 0 | H34: =D34-E34-F34-G34 -> 4 | J34: DIETA DE POLLO | K34: 1
A35: CAMARON | B35: ='21.09.25'!H35 -> 0 | D35: =B35+C35 -> 0 | E35: =IFERROR(VLOOKUP("CHUPE DE CAMARORES",J:K,2,FALSE),0)+IFERROR(VLOOKUP("CAMARONES AL AJO",J:K,2,FALSE),0)+IFERROR(VLOOKUP("CEVICHE DE CAMARONES",J:K,2,FALSE),0)+IFERROR(VLOOKUP("ARROZ CON CAMARONES",J:K,2,FALSE),0)+IFERROR(VLOOKUP("CAUSA DE CAMARONES",J:K,2,FALSE),0) -> 0 | H35: =D35-E35-F35-G35 -> 0
A36: MIXTURA | B36: ='21.09.25'!H36 -> 4 | D36: =B36+C36 -> 4 | E36: =IFERROR(VLOOKUP("PIQUEO FRUTOS DEL MAR",J:K,2,FALSE)*2,0)+IFERROR(VLOOKUP("CEVICHE MIXTO DE MARISCOS",J:K,2,FALSE),0)+IFERROR(VLOOKUP("ARROZ C/MARISCOS",J:K,2,FALSE),0)+IFERROR(VLOOKUP("TORTILLA DE MARISCOS C/ ARROZ",J:K,2,FALSE),0)+IFERROR(VLOOKUP("CHAUFA DE MARISCOS",J:K,2,FALSE),0)+IFERROR(VLOOKUP("PARIHUELA DE MARISCOS",J:K,2,FALSE),0)+IFERROR(VLOOKUP("PICANTE DE MARISCOS",J:K,2,FALSE),0)+IFERROR(VLOOKUP("TACU TACU EN SALSA DE MARISCOS",J:K,2,FALSE),0)+IFERROR(VLOOKUP("TRÍO DE CAUSAS",J:K,2,FALSE),0)+IFERROR(VLOOKUP("CHICHARRON MIXTO DE MARISCOS",J:K,2,FALSE),0)+IFERROR(VLOOKUP("LENGUADO O CORVINA FRITA EN S/MARISCOS",J:K,2,FALSE),0)+IFERROR(VLOOKUP("TACU TACU C/LENGUADO EN SALSA DE MARISCOS",J:K,2,FALSE),0)+IFERROR(VLOOKUP("RISOTTO FRUTOS DEL MAR",J:K,2,FALSE),0)+IFERROR(VLOOKUP("TRES CAUSAS UNA PARRILLA",J:K,2,FALSE)/2,0) -> 1 | H36: =D36-$E$36-F36-G36 -> 3
A37: TOLLO | B37: ='21.09.25'!H37 -> 4 | C37: 10 | D37: =B37+C37 -> 14 | E37: =IFERROR(VLOOKUP("PIQUEO FRUTOS DEL MAR",J:K,2,FALSE)*2,0)+IFERROR(VLOOKUP("CHICHARRON PESCA DEL DIA",J:K,2,FALSE),0)+IFERROR(VLOOKUP("CEVICHE PESCA DEL DIA",J:K,2,FALSE),0)+IFERROR(VLOOKUP("LECHE DE TIGRE",J:K,2,FALSE),0)+IFERROR(VLOOKUP("1/2 LECHE DE TIGRE",J:K,2,FALSE)/2,0)+IFERROR(VLOOKUP("TRILOGIA DE LECHES DE TIGRE ",J:K,2,FALSE),0)+IFERROR(VLOOKUP("CAUSA EN SALSA ACEVICHADA ",J:K,2,FALSE),0)+IFERROR(VLOOKUP("CAUSA DE LA CASA",J:K,2,FALSE),0) -> 1 | H37: =D37-$E$36-F37-G37 -> 13
A38: LANGOSTINO | B38: ='21.09.25'!H38 -> 4 | D38: =B38+C38 -> 4 | E38: =IFERROR(VLOOKUP("LANGOSTINO THAI",J:K,2,FALSE),0)+IFERROR(VLOOKUP("LANGOSTINOS CROCANTES CON PALTA BRACEADA",J:K,2,FALSE),0)+IFERROR(VLOOKUP("ARROZ C/LANGOSTINOS",J:K,2,FALSE),0)+IFERROR(VLOOKUP("SALTADO MAR Y TIERRA",J:K,2,FALSE)/2,0)+IFERROR(VLOOKUP("CAUSA DE LANGOSTINOS",J:K,2,FALSE),0)+IFERROR(VLOOKUP("TACU TACU C/ LENGUADO EN SALSA DE LANGOSTINOS",J:K,2,FALSE),0)+IFERROR(VLOOKUP("TACU TACU C/LOMO FINO EN SALSA DE LANGOSTINOS",J:K,2,FALSE),0) -> 0 | H38: =D38-$E$36-F38-G38 -> 3

Sheet 23.09.25
A1: KARDEX COCINA - FECHA 23.09.25
A2: ENTRADAS | B2: SALDO INICIAL | C2: INGRESOS | D2: TOTAL | E2: VENTA | F2: MENU | G2: MERMA/ VARIOS | H2: SALDO FINAL | I2: OBSERVACION
A3: TAMALES | B3: ='22.09.25'!H3 -> 5 | D3: =B3+C3 -> 5 | E3: =IFERROR(VLOOKUP("TAMAL DE LA CASA CON ZARZA CRIOLLAL",J:K,2,FALSE),"0") -> 0 | H3: =D3-E3-F3-G3 -> 5 | J3: AJI DE GALLINA | K3: 3
A4: HUMITAS | B4: ='22.09.25'!H4 -> 0 | D4: =B4+C4 -> 0 | E4: =IFERROR(VLOOKUP("HUMITA DOÑA FRESIA C/AJI DE GALLINA",J:K,2,FALSE),"0") -> 0 | H4: =D4-E4-F4-G4 -> 0 | J4: AJIACO DE CUY(1/2 CUY) C/ARROZ | K4: 5
A5: PAPA RELLENA | B5: ='22.09.25'!H5 -> 1 | C5: 5 | D5: =B5+C5 -> 6 | E5: =IFERROR(VLOOKUP(A$5,J:K,2,FALSE),0)+IFERROR(VLOOKUP("PIQUEO PERUANISIMO",J:K,2,FALSE),0) -> 1 | H5: =D5-E5-F5-G5 -> 5 | J5: ARROZ C/MARISCOS | K5: 3
A6: SANGRECITA | B6: ='22.09.25'!H6 -> 4 | C6: 5 | D6: =B6+C6 -> 9 | E6: =IFERROR(VLOOKUP("SANGRECITA C/YUCA",J:K,2,FALSE),"0") -> 8 | H6: =D6-E6-F6-G6 -> 1 | J6: ARROZ C/PATO | K6: 4
A7: AJI DE GALLINA | B7: ='22.09.25'!H7 -> 9 | D7: =B7+C7 -> 9 | E7: =IFERROR(VLOOKUP("HUMITA DOÑA FRESIA C/AJI DE GALLINA", J:K,2, FALSE)/2, 0) + IFERROR(VLOOKUP("AJI DE GALLINA",J:K,2, FALSE), 0) -> 3 | H7: =D7-E7-F7-G7 -> 6 | J7: ARROZ C/PATO DESHUESADO | K7: 3
A8: MOLLEJITA | B8: ='22.09.25'!H8 -> 8 | D8: =B8+C8 -> 8 | E8: =IFERROR(VLOOKUP("MOLLEJITAS GUISADAS",J:K,2,FALSE),"0")+IFERROR(VLOOKUP("PIQUEO DOÑA FRESIA",J:K,2,FALSE),0) -> 3 | H8: =D8-E8-F8-G8 -> 5 | J8: ASADO DE RES CON ARROZ Y PURE | K8: 5
A9: PATITA | B9: ='22.09.25'!H9 -> 7.5 | C9: 5 | D9: =B9+C9 -> 12.5 | E9: =IFERROR(VLOOKUP("1/2 PATITA EN FIAMBRE",J:K,2, FALSE)/2, 0) + IFERROR(VLOOKUP("PATITA EN FIAMBRE",J:K, 2, FALSE), 0) -> 2 | G9: 6 | H9: =D9-E9-F9-G9 -> 4.5 | I9: SE ENVIO A SAN ANDRES | J9: BISTEC DE LOMO FINO A LO POBRE | K9: 5
A10: CECINA | B10: ='22.09.25'!H10 -> 1 | C10: 5 | D10: =B10+C10 -> 6 | E10: =IFERROR(VLOOKUP("CECINAS DE LOMO C/YUCA",J:K,2,FALSE),"0")+IFERROR(VLOOKUP("PIQUEO DOÑA FRESIA",J:K,2,FALSE)/2,0) -> 1 | H10: =D10-E10-F10-G10 -> 5 | J10: CABRITO C/ARROZ FRIJOL Y YUCA | K10: 15
A11: ADOBO | B11: ='22.09.25'!H11 -> 7 | D11: =B11+C11 -> 7 | E11: =IFERROR(VLOOKUP("CARNE DE CERDO ADOBADA",J:K,2,FALSE),0) -> 1 | H11: =D11-E11-F11-G11 -> 6 | J11: CABRITO DESHUESADO | K11: 11
A12: SANCOCHADO | B12: ='22.09.25'!H12 -> 0 | D12: =B12+C12 -> 0 | E12: =IFERROR(VLOOKUP("SANCOCHADO 450g.",J:K,2,FALSE),0) -> 0 | H12: =D12-E12-F12-G12 -> 0 | J12: CAUSA DE LA CASA | K12: 2
A13: SHAMBAR | B13: ='22.09.25'!H13 -> 3 | D13: =B13+C13 -> 3 | E13: =IFERROR(VLOOKUP(A13,J:K,2,FALSE),0) -> 0 | H13: =D13-E13-F13-G13 -> 3 | J13: CAUSA DE LOMO FINO SALTADO | K13: 1
A14: CALDO DE GALLINA | B14: ='22.09.25'!H14 -> 0 | D14: =B14+C14 -> 0 | E14: =IFERROR(VLOOKUP(A14,J:K,2,FALSE),0) -> 0 | H14: =D14-E14-F14-G14 -> 0 | J14: CECINAS DE LOMO C/YUCA | K14: 1
A15: GUISOS | J15: CEVICHE DE LENGUADO | K15: 1
A16: ASADO | B16: ='22.09.25'!H16 -> 20 | C16: 2 | D16: =B16+C16 -> 22 | E16: =IFERROR(VLOOKUP("ASADO DE RES CON ARROZ Y PURE",J:K,2,FALSE),0)+IFERROR(VLOOKUP("FETUCCINI AL P.C/ ASADO DE RES",J:K,2,FALSE),"0")+IFERROR(VLOOKUP("FETUCCINI A LO ALFR.C/ ASADO DE RES",J:K,2,FALSE),"0")+IFERROR(VLOOKUP("FETUCCINI A LA H.C/ ASADO DE RES",J:K,2,FALSE),"0")+IFERROR(VLOOKUP("SANDWICH DE ASADO DE RES",J:K,2,FALSE),0)+IFERROR(VLOOKUP("RISOTTO A LA H. C/ASADO",J:K,2,FALSE),0)+IFERROR(VLOOKUP("RISOTTO AL PESTO C/ASADO",J:K,2,FALSE),0)+IFERROR(VLOOKUP("TACU TACU C/ ASADO DE RES",J:K,2,FALSE),0) -> 7 | H16: =D16-E16-F16-G16 -> 15 | J16: CHAUFA DE MARISCOS | K16: 1
A17: CUY | B17: ='22.09.25'!H17 -> 5 | C17: 4 | D17: =B17+C17 -> 9 | E17: =IFERROR(VLOOKUP("AJIACO DE CUY(1/2 CUY) C/ARROZ",J:K,2,FALSE),"0") -> 5 | H17: =D17-E17-F17-G17 -> 4 | J17: CHICHARRON DE LANGOSTINOS | K17: 1
A18: ALBONDIGA | B18: ='22.09.25'!H18 -> 4 | D18: =B18+C18 -> 4 | E18: =IFERROR(VLOOKUP("ALBONDIGA CON ARROZ",J:K,2,FALSE),"0") -> 2 | H18: =D18-E18-F18-G18 -> 2 | J18: CORVINA SUDADA | K18: 4
A19: ARROZ C. PATO | B19: ='22.09.25'!H19 -> 0 | C19: 10 | D19: =B19+C19 -> 10 | E19: =IFERROR(VLOOKUP("ARROZ C/PATO DESHUESADO", J:K, 2, FALSE)*2, 0)+IFERROR(VLOOKUP("ARROZ C/PATO",J:K,2,FALSE),"0") -> 10 | H19: =D19-E19-F19-G19 -> 0 | J19: DIETA DE POLLO | K19: 1
A20: CABRITO NORMAL | B20: ='22.09.25'!H20 -> 40 | D20: =B20+C20 -> 40 | E20: =IFERROR(VLOOKUP("CABRITO C/ TACU TACU",J:K,2,FALSE),"0")+IFERROR(VLOOKUP("CABRITO C/ARROZ FRIJOL Y YUCA",J:K,2,FALSE),"0")+IFERROR(VLOOKUP("PRESA DE CABRITO",J:K,2,FALSE),"0")+IFERROR(VLOOKUP("CABRITO DESHUESADO",J:K,2,FALSE)*2,"0")+IFERROR(VLOOKUP("TACU TACU C/ CABRITO DESHUESADO",J:K,2,FALSE)*2,"0")+IFERROR(VLOOKUP("PIQUEO DOÑA FRESIA",J:K,2,FALSE)*2,"0") -> 39 | H20: =D20-E20-F20-G20 -> 1 | J20: ENSALADA MIXTA PERSONAL | K20: 1
A21: CABRITO DESHUESADO | B21: ='22.09.25'!H21 | D21: =B21+C21 -> 0 | J21: FETUCCINI A LA H.C/ FILETE DE POLLO | K21: 1
A22: PATO ESTOFADO | B22: ='22.09.25'!H22 -> 28 | C22: 5 | D22: =B22+C22 -> 33 | E22: =IFERROR(VLOOKUP("PATO ESTOFADO C/ARROZ Y FRIJOL",J:K,2,FALSE),0)+IFERROR(VLOOKUP("PATO ESTOFADO DESHUESADO",J:K,2,FALSE)*2,0)+IFERROR(VLOOKUP("TACU TACU C/ PATO ESTOF. DESHUESADO",J:K,2,FALSE)*2,0)+IFERROR(VLOOKUP("PIQUEO DOÑA FRESIA",J:K,2,FALSE)*2,0)+IFERROR(VLOOKUP("PATO ESTOFADO CON TACU TACU",J:K,2,FALSE),0) -> 14 | H22: =D22-E22-F22-G22 -> 19 | J22: FETUCCINI A LA H.C/ MILANESA | K22: 1
A23: PEPIAN | B23: ='22.09.25'!H23 -> 0 | D23: =B23+C23 -> 0 | E23: =IFERROR(VLOOKUP("PEPIAN DE PAVO",J:K,2,FALSE),"0")+IFERROR(VLOOKUP("PRESA DE PAVA",J:K,2,FALSE),0)+IFERROR(VLOOKUP("SANDWICH DE PAVO",J:K,2,FALSE),0) -> 0 | H23: =D23-E23-F23-G23 -> 0 | J23: FETUCCINI A LO ALFR.C/ FILETE DE POLLO | K23: 1
A24: CORVINA GUISADA | B24: ='22.09.25'!H24 -> 5 | D24: =B24+C24 -> 5 | E24: =IFERROR(VLOOKUP("CORVINA GUISADA C/E CHOCLO",J:K,2,FALSE),"0") -> 0 | G24: 1 | H24: =D24-E24-F24-G24 -> 4 | I24: DESCARTE MAL ESTADO | J24: FETUCCINI A LO ALFR.C/ BISTEC APANADO | K24: 1
A25: FRITURAS | J25: FETUCCINI A LO ALFR.C/ BISTEC DE LOMO | K25: 1
A26: LOMO SALTADO | B26: ='22.09.25'!H26 -> 0 | C26: 10 | D26: =B26+C26 -> 10 | E26: =IFERROR(VLOOKUP("LOMO SALTADO C/ARROZ",J:K,2,FALSE),0)+IFERROR(VLOOKUP("TACU TACU C/ LOMO SALTADO",J:K,2,FALSE),0)+IFERROR(VLOOKUP("LOMO SALTADO A LO POBRE",J:K,2,FALSE),0)++IFERROR(VLOOKUP("FETUCCINI AL P.C/ LOMO SALTADO",J:K,2,FALSE),"0")+IFERROR(VLOOKUP("FETUCCINI A LO ALFR.C/ LOMO SALTADO",J:K,2,FALSE),"0")+IFERROR(VLOOKUP("FETUCCINI A LA H.C/ LOMO SALTADO",J:K,2,FALSE),"0")+IFERROR(VLOOKUP("RISOTTO A LA H. C/ LOMO SALTADO",J:K,2,FALSE),0)+IFERROR(VLOOKUP("RISOTTO PESTO C/LOMO SALTADO",J:K,2,FALSE),0)+IFERROR(VLOOKUP("CAUSA DE LOMO FINO SALTADO",J:K,2,FALSE)/2,0)+IFERROR(VLOOKUP("LOMO SALTADO A NUESTRO ESTILO",J:K,2,FALSE),0)+IFERROR(VLOOKUP("SANDWICH DE LOMO FINO SALTADO",J:K,2,FALSE)/2,0)+IFERROR(VLOOKUP("LOMO SALTADO C/ ARROZ Y FRIJOL",J:K,2,FALSE),0)+IFERROR(VLOOKUP("SALTADO MAR Y TIERRA ",$J:$K,2,FALSE)/2,0)+IFERROR(VLOOKUP("LOMO EN NUESTRO ESTILO",$J:$K,2,FALSE),0) -> 3.5 | H26: =D26-E26-F26-G26 -> 6.5 | J26: FETUCCINI AL P.C/ ASADO DE RES | K26: 2
A27: FILETE DE POLLO CARTA | B27: ='22.09.25'!H27 -> 4 | C27: 6 | D27: =B27+C27 -> 10 | E27: =IFERROR(VLOOKUP("FILETE DE POLLO A LA PLANCHA",J:K,2,FALSE),"0")+IFERROR(VLOOKUP("FETUCCINI A LO ALFR.C/ FILETE DE POLLO",J:K,2,FALSE),"0")+IFERROR(VLOOKUP("FETUCCINI A LA H.C/ FILETE DE POLLO",J:K,2,FALSE),"0")+IFERROR(VLOOKUP("FETUCCINI AL P.C/ FILETE DE POLLO",J:K,2,FALSE),"0")+IFERROR(VLOOKUP("PIQUEO PERUANISIMO",J:K,2,FALSE)*2,0)+IFERROR(VLOOKUP("DIETA DE POLLO",J:K,2,FALSE),0)+IFERROR(VLOOKUP("RISOTTO PESTO C/FILETE DE POLLO",J:K,2,FALSE),0)+IFERROR(VLOOKUP("POLLO SALTADO C/ ARROZ Y PAPAS FRITAS",J:K,2,FALSE),0)+IFERROR(VLOOKUP("PRESA DE FILETE DE POLLO",J:K,2,FALSE),0)+IFERROR(VLOOKUP("SALTADO MAR Y TIERRA ",J:K,2,FALSE)/2,0)+IFERROR(VLOOKUP("CAUSA DE POLLO ",J:K,2,FALSE),0)+IFERROR(VLOOKUP("SANDWICH DE POLLO ",J:K,2,FALSE),0) -> 9 | H27: =D27-E27-F27-G27 -> 1 | J27: FETUCCINI AL P.C/ BISTEC APANADO | K27: 1
A28: MILANESA CARTA | B28: ='22.09.25'!H28 -> 6 | D28: =B28+C28 -> 6 | E28: =IFERROR(VLOOKUP("MILANESA DE POLLO",J:K,2,FALSE),"0")+IFERROR(VLOOKUP("FETUCCINI AL P.C/ MILANESA",J:K,2,FALSE),"0")+IFERROR(VLOOKUP("FETUCCINI A LO ALFR.C/ MILANESA",J:K,2,FALSE),"0")+IFERROR(VLOOKUP("FETUCCINI A LA H.C/ MILANESA",J:K,2,FALSE),"0")+IFERROR(VLOOKUP("MILANESA DE POLLO A LO POBRE",J:K,2,FALSE),"0")+IFERROR(VLOOKUP("RISOTTO PESTO C/MILANESA",J:K,2,FALSE),0)+IFERROR(VLOOKUP("TACU TACU C/ MILANESA",J:K,2,FALSE),0)+IFERROR(VLOOKUP("RISOTTO A LA H. C/MILANESA DE POLLO",J:K,2,FALSE),0) -> 1 | H28: =D28-E28-F28-G28 -> 5 | J28: FILETE DE POLLO A LA PLANCHA | K28: 6
A29: BISTEC CARTA | B29: ='22.09.25'!H29 -> 0 | C29: 12 | D29: =B29+C29 -> 12 | E29: =IFERROR(VLOOKUP("TACU TACU C/ BISTEC A LO POBRE",J:K,2,FALSE),0)+IFERROR(VLOOKUP("BISTEC DE LOMO FINO A LO POBRE",J:K,2,FALSE),0)+IFERROR(VLOOKUP("FETUCCINI AL P.C/ BISTEC DE LOMO 250 G",J:K,2,FALSE),"0")+IFERROR(VLOOKUP("FETUCCINI A LO ALFR.C/ BISTEC DE LOMO 250 G",J:K,2,FALSE),"0")+IFERROR(VLOOKUP("FETUCCINI A LA H.C/ BISTEC DE LOMO 250 G",J:K,2,FALSE),"0")+IFERROR(VLOOKUP("FETUCCINI AL P.C/ BISTEC DE LOMO APANADO",J:K,2,FALSE),"0")+IFERROR(VLOOKUP("FETUCCINI A LO ALFR.C/ BISTEC DE LOMO APANADO",J:K,2,FALSE),"0")+IFERROR(VLOOKUP("FETUCCINI A LA H.C/ BISTEC DE LOMO APANADO",J:K,2,FALSE),"0")+IFERROR(VLOOKUP("RISOTTO A LA H. BISTEC DE LOMO 250 G",J:K,2,FALSE),0)+IFERROR(VLOOKUP("RISOTTO PESTO C/BISTEC DE LOMO 250 G",J:K,2,FALSE),0)+IFERROR(VLOOKUP("BISTEC DE LOMO FINO A LA PLANCHA",J:K,2,FALSE),0)+IFERROR(VLOOKUP("LOMO A LAS 3 PIMIENTAS",J:K,2,FALSE),0)+IFERROR(VLOOKUP("LOMO FINO EN SALSA D CHAMPIÑONES",J:K,2,FALSE),0)+IFERROR(VLOOKUP("BISTEC DE LOMO FINO APANADO",J:K,2,FALSE),0)+IFERROR(VLOOKUP("TACU TACU C/LOMO FINO EN SALSA DE LANGOSTINOS",J:K,2,FALSE),0) -> 7 | H29: =D29-E29-F29-G29 -> 5 | J29: LENGUADO A LA PLANCHA CON ARROZ | K29: 2
A30: CHICHARRON DE POLLO | B30: ='22.09.25'!H30 -> 0 | D30: =B30+C30 -> 0 | E30: =IFERROR(VLOOKUP("CHICHARRON DE POLLO C/ PAPAS FRITAS",J:K,2,FALSE),0)+IFERROR(VLOOKUP("1/2 PORC. CHICHARRON DE POLLO",J:K,2,FALSE),0) -> 0 | H30: =D30-E30-F30-G30 -> 0 | J30: LENGUADO APANADO C/ARROZ Y FRIJOL | K30: 1
A31: PESCADOS Y MARISCOS | D31: =B31+C31 -> 0 | H31: =D31-E31-F31-G31 -> 0 | J31: LOMO FINO EN SALSA D CHAMPIÑONES | K31: 2
A32: LENGUADO | B32: ='22.09.25'!H32 -> 12 | C32: 17 | D32: =B32+C32 -> 29 | E32: =IFERROR(VLOOKUP("CEVICHE MIXTO DE MARISCOS",J:K,2,FALSE),0)+IFERROR(VLOOKUP("CEVICHE DE LENGUADO",J:K,2,FALSE),0)+IFERROR(VLOOKUP("LENGUADO A LA PLANCHA CON ARROZ",J:K,2,FALSE),0)+IFERROR(VLOOKUP("LENGUADO A LO MACHO CON YUCA",J:K,2,FALSE),0)+IFERROR(VLOOKUP("LENGUADO APANADA C/ARROZ Y FRIJOL",J:K,2,FALSE),0)+IFERROR(VLOOKUP("LENGUADO ESCABECHADO C/ARROZ Y CAMOTE",J:K,2,FALSE),0)+IFERROR(VLOOKUP("TACU TACU C/ LENGUADO EN SALSA DE LANGOSTINOS",J:K,2,FALSE),0)+IFERROR(VLOOKUP("TACU TACU C/LENGUADO EN SALSA DE MARISCOS",J:K,2,FALSE),0)+IFERROR(VLOOKUP("TIRADITO DE LENGUADO A LAS DOS CREMAS",J:K,2,FALSE),0)+IFERROR(VLOOKUP("TIRADITO DE LENGUADO O SIMILAR",J:K,2,FALSE),0)+IFERROR(VLOOKUP("CHICHARRON DE LENGUADO",J:K,2,FALSE),0)+IFERROR(VLOOKUP("JALEA DE LENGUADO O SIMILAR",J:K,2,FALSE),0)+IFERROR(VLOOKUP("LENGUADO O CORVINA FRITA C/ARROZ Y YUCA",J:K,FALSE),0)+IFERROR(VLOOKUP("LENGUADO O CORVINA FRITA EN S/MARISCOS",J:K,2,FALSE),0)+IFERROR(VLOOKUP("LENGUADO O SIMILAR AL AJO C/ARROZ",J:K,2,FALSE),0)+IFERROR(VLOOKUP("LENGUADO A LA MEUNIERE",J:K,2,FALSE),0)+IFERROR(VLOOKUP("TACU TACU C/ LENGUADO A LO MACHO",J:K,2,FALSE),0)+IFERROR(VLOOKUP("CHICHARRON MIXTO DE MARISCOS",J:K,2,FALSE),0)+IFERROR(VLOOKUP("FUENTE DE CEVICHE DE CORVINA O LENGUADO",J:K,2,FALSE)*2,0)+IFERROR(VLOOKUP("CAUSA DE LA CASA ",J:K,2,FALSE),0)+IFERROR(VLOOKUP("TACU TACU C/ LENGUDO EN SALSA DE LANGOSTINOS",J:K,2,FALSE),0) -> 4 | H32: =D32-E32-F32-G32 -> 25 | J32: LOMO SALTADO C/ARROZ | K32: 2
A33: CORVINA | B33: ='22.09.25'!H33 -> 2 | C33: 6 | D33: =B33+C33 -> 8 | E33: =IFERROR(VLOOKUP("CORVINA SUDADA",J:K,2,FALSE),0)+IFERROR(VLOOKUP("CHUPE DE CORVINA",J:K,2,FALSE),0) -> 4 | H33: =D33-E33-F33-G33 -> 4 | J33: MOLLEJITAS GUISADAS | K33: 3
A34: PULPO | B34: ='22.09.25'!H34 -> 4 | C34: 5 | D34: =B34+C34 -> 9 | E34: =IFERROR(VLOOKUP("PULPO ANTICUCHERO 250G",J:K,2,FALSE),0)+IFERROR(VLOOKUP("PULPO AL OLIVO 200G",J:K,2,FALSE),0)+IFERROR(VLOOKUP("CEVICHE DE PULPO",J:K,2,FALSE),0)+IFERROR(VLOOKUP("CAUSA DE PULPO AL OLIVO",J:K,2,FALSE),0)+IFERROR(VLOOKUP("CEVICHE DE PULPO",J:K,2,FALSE)*2,0)+IFERROR(VLOOKUP("TRES CAUSAS UNA PARRILLA",J:K,2,FALSE)/2,0) -> 1 | H34: =D34-E34-F34-G34 -> 8 | J34: PAPA A LA HUANCAINA | K34: 2
A35: CAMARON | B35: ='22.09.25'!H35 -> 0 | D35: =B35+C35 -> 0 | E35: =IFERROR(VLOOKUP("CHUPE DE CAMARORES",J:K,2,FALSE),0)+IFERROR(VLOOKUP("CAMARONES AL AJO",J:K,2,FALSE),0)+IFERROR(VLOOKUP("CEVICHE DE CAMARONES",J:K,2,FALSE),0)+IFERROR(VLOOKUP("ARROZ CON CAMARONES",J:K,2,FALSE),0)+IFERROR(VLOOKUP("CAUSA DE CAMARONES",J:K,2,FALSE),0) -> 0 | H35: =D35-E35-F35-G35 -> 0 | J35: PAPA RELLENA | K35: 1
A36: MIXTURA | B36: ='22.09.25'!H36 -> 3 | C36: 25 | D36: =B36+C36 -> 28 | E36: =IFERROR(VLOOKUP("PIQUEO FRUTOS DEL MAR",J:K,2,FALSE)*2,0)+IFERROR(VLOOKUP("CEVICHE MIXTO DE MARISCOS",J:K,2,FALSE),0)+IFERROR(VLOOKUP("ARROZ C/MARISCOS",J:K,2,FALSE),0)+IFERROR(VLOOKUP("TORTILLA DE MARISCOS C/ ARROZ",J:K,2,FALSE),0)+IFERROR(VLOOKUP("CHAUFA DE MARISCOS",J:K,2,FALSE),0)+IFERROR(VLOOKUP("PARIHUELA DE MARISCOS",J:K,2,FALSE),0)+IFERROR(VLOOKUP("PICANTE DE MARISCOS",J:K,2,FALSE),0)+IFERROR(VLOOKUP("TACU TACU EN SALSA DE MARISCOS",J:K,2,FALSE),0)+IFERROR(VLOOKUP("TRÍO DE CAUSAS",J:K,2,FALSE),0)+IFERROR(VLOOKUP("CHICHARRON MIXTO DE MARISCOS",J:K,2,FALSE),0)+IFERROR(VLOOKUP("LENGUADO O CORVINA FRITA EN S/MARISCOS",J:K,2,FALSE),0)+IFERROR(VLOOKUP("TACU TACU C/LENGUADO EN SALSA DE MARISCOS",J:K,2,FALSE),0)+IFERROR(VLOOKUP("RISOTTO FRUTOS DEL MAR",J:K,2,FALSE),0)+IFERROR(VLOOKUP("TRES CAUSAS UNA PARRILLA",J:K,2,FALSE)/2,0) -> 6 | H36: =D36-$E$36-F36-G36 -> 22 | J36: PATO ESTOFADO C/ARROZ Y FRIJOL | K36: 4
A37: TOLLO | B37: ='22.09.25'!H37 -> 13 | D37: =B37+C37 -> 13 | E37: =IFERROR(VLOOKUP("PIQUEO FRUTOS DEL MAR",J:K,2,FALSE)*2,0)+IFERROR(VLOOKUP("CHICHARRON PESCA DEL DIA",J:K,2,FALSE),0)+IFERROR(VLOOKUP("CEVICHE PESCA DEL DIA",J:K,2,FALSE),0)+IFERROR(VLOOKUP("LECHE DE TIGRE",J:K,2,FALSE),0)+IFERROR(VLOOKUP("1/2 LECHE DE TIGRE",J:K,2,FALSE)/2,0)+IFERROR(VLOOKUP("TRILOGIA DE LECHES DE TIGRE ",J:K,2,FALSE),0)+IFERROR(VLOOKUP("CAUSA EN SALSA ACEVICHADA ",J:K,2,FALSE),0)+IFERROR(VLOOKUP("CAUSA DE LA CASA",J:K,2,FALSE),0) -> 4 | H37: =D37-$E$36-F37-G37 -> 7 | J37: PATO ESTOFADO DESHUESADO | K37: 5
A38: LANGOSTINO | B38: ='22.09.25'!H38 -> 3 | C38: 15 | D38: =B38+C38 -> 18 | E38: =IFERROR(VLOOKUP("LANGOSTINO THAI",J:K,2,FALSE),0)+IFERROR(VLOOKUP("LANGOSTINOS CROCANTES CON PALTA BRACEADA",J:K,2,FALSE),0)+IFERROR(VLOOKUP("ARROZ C/LANGOSTINOS",J:K,2,FALSE),0)+IFERROR(VLOOKUP("SALTADO MAR Y TIERRA",J:K,2,FALSE)/2,0)+IFERROR(VLOOKUP("CAUSA DE LANGOSTINOS",J:K,2,FALSE),0)+IFERROR(VLOOKUP("TACU TACU C/ LENGUADO EN SALSA DE LANGOSTINOS",J:K,2,FALSE),0)+IFERROR(VLOOKUP("TACU TACU C/LOMO FINO EN SALSA DE LANGOSTINOS",J:K,2,FALSE),0) -> 1 | H38: =D38-$E$36-F38-G38 -> 12 | J38: PIQUEO FRUTOS DEL MAR | K38: 1
D39: =B39+C39 -> 0 | H39: =D39-E39-F39-G39 -> 0 | J39: PORCION DE ARROZ | K39: 3
B40: ='22.09.25'!H40 | J40: SANGRECITA C/YUCA | K40: 8
...

Sheet 24.09.25
A1: KARDEX COCINA - FECHA 24.09.25
A2: ENTRADAS | B2: SALDO INICIAL | C2: INGRESOS | D2: TOTAL | E2: VENTA | F2: MENU | G2: MERMA/ VARIOS | H2: SALDO FINAL | I2: OBSERVACION
A3: TAMALES | B3: ='23.09.25'!H3 -> 5 | D3: =B3+C3 -> 5 | E3: =IFERROR(VLOOKUP("TAMAL DE LA CASA CON ZARZA CRIOLLAL",J:K,2,FALSE),"0") -> 0 | H3: =D3-E3-F3-G3 -> 5 | J3: AJI DE GALLINA | K3: 4
A4: HUMITAS | B4: ='23.09.25'!H4 -> 0 | D4: =B4+C4 -> 0 | E4: =IFERROR(VLOOKUP("HUMITA DOÑA FRESIA C/AJI DE GALLINA",J:K,2,FALSE),"0") -> 0 | H4: =D4-E4-F4-G4 -> 0 | J4: ARROZ C/MARISCOS | K4: 1
A5: PAPA RELLENA | B5: ='23.09.25'!H5 -> 5 | D5: =B5+C5 -> 5 | E5: =IFERROR(VLOOKUP(A$5,J:K,2,FALSE),0)+IFERROR(VLOOKUP("PIQUEO PERUANISIMO",J:K,2,FALSE),0) -> 1 | H5: =D5-E5-F5-G5 -> 4 | J5: ARROZ C/PATO | K5: 1
A6: SANGRECITA | B6: ='23.09.25'!H6 -> 1 | C6: 9 | D6: =B6+C6 -> 10 | E6: =IFERROR(VLOOKUP("SANGRECITA C/YUCA",J:K,2,FALSE),"0") -> 8 | H6: =D6-E6-F6-G6 -> 2 | J6: ARROZ C/PATO DESHUESADO | K6: 4
A7: AJI DE GALLINA | B7: ='23.09.25'!H7 -> 6 | C7: 5 | D7: =B7+C7 -> 11 | E7: =IFERROR(VLOOKUP("HUMITA DOÑA FRESIA C/AJI DE GALLINA", J:K,2, FALSE)/2, 0) + IFERROR(VLOOKUP("AJI DE GALLINA",J:K,2, FALSE), 0) -> 4 | H7: =D7-E7-F7-G7 -> 7 | J7: ASADO DE RES CON ARROZ Y PURE | K7: 3
A8: MOLLEJITA | B8: ='23.09.25'!H8 -> 5 | D8: =B8+C8 -> 5 | E8: =IFERROR(VLOOKUP("MOLLEJITAS GUISADAS",J:K,2,FALSE),"0")+IFERROR(VLOOKUP("PIQUEO DOÑA FRESIA",J:K,2,FALSE),0) -> 1 | G8: 1.5 | H8: =D8-E8-F8-G8 -> 2.5 | I8: SE ENVIO A SAN ANDRES | J8: BISTEC DE LOMO FINO A LA PLANCHA | K8: 3
A9: PATITA | B9: ='23.09.25'!H9 -> 4.5 | D9: =B9+C9 -> 4.5 | E9: =IFERROR(VLOOKUP("1/2 PATITA EN FIAMBRE",J:K,2, FALSE)/2, 0) + IFERROR(VLOOKUP("PATITA EN FIAMBRE",J:K, 2, FALSE), 0) -> 2.5 | H9: =D9-E9-F9-G9 -> 2 | J9: BISTEC DE LOMO FINO A LO POBRE | K9: 3
A10: CECINA | B10: ='23.09.25'!H10 -> 5 | D10: =B10+C10 -> 5 | E10: =IFERROR(VLOOKUP("CECINAS DE LOMO C/YUCA",J:K,2,FALSE),"0")+IFERROR(VLOOKUP("PIQUEO DOÑA FRESIA",J:K,2,FALSE)/2,0) -> 1.5 | H10: =D10-E10-F10-G10 -> 3.5 | J10: CABRITO C/ARROZ FRIJOL Y YUCA | K10: 10
A11: ADOBO | B11: ='23.09.25'!H11 -> 6 | D11: =B11+C11 -> 6 | E11: =IFERROR(VLOOKUP("CARNE DE CERDO ADOBADA",J:K,2,FALSE),0) -> 2 | H11: =D11-E11-F11-G11 -> 4 | J11: CABRITO DESHUESADO | K11: 9
A12: SANCOCHADO | B12: ='23.09.25'!H12 -> 0 | C12: 4 | D12: =B12+C12 -> 4 | E12: =IFERROR(VLOOKUP("SANCOCHADO 450g.",J:K,2,FALSE),0) -> 4 | H12: =D12-E12-F12-G12 -> 0 | J12: CARNE DE CERDO ADOBADA | K12: 2
A13: SHAMBAR | B13: ='23.09.25'!H13 -> 3 | D13: =B13+C13 -> 3 | E13: =IFERROR(VLOOKUP(A13,J:K,2,FALSE),0) -> 0 | H13: =D13-E13-F13-G13 -> 3 | J13: CAUSA DE LA CASA | K13: 2
A14: CALDO DE GALLINA | B14: ='23.09.25'!H14 -> 0 | D14: =B14+C14 -> 0 | E14: =IFERROR(VLOOKUP(A14,J:K,2,FALSE),0) -> 0 | H14: =D14-E14-F14-G14 -> 0 | J14: CAUSA DE PULPO AL OLIVO | K14: 2
A15: GUISOS | J15: CECINAS DE LOMO C/YUCA | K15: 1
A16: ASADO | B16: ='23.09.25'!H16 -> 15 | D16: =B16+C16 -> 15 | E16: =IFERROR(VLOOKUP("ASADO DE RES CON ARROZ Y PURE",J:K,2,FALSE),0)+IFERROR(VLOOKUP("FETUCCINI AL P.C/ ASADO DE RES",J:K,2,FALSE),"0")+IFERROR(VLOOKUP("FETUCCINI A LO ALFR.C/ ASADO DE RES",J:K,2,FALSE),"0")+IFERROR(VLOOKUP("FETUCCINI A LA H.C/ ASADO DE RES",J:K,2,FALSE),"0")+IFERROR(VLOOKUP("SANDWICH DE ASADO DE RES",J:K,2,FALSE),0)+IFERROR(VLOOKUP("RISOTTO A LA H. C/ASADO",J:K,2,FALSE),0)+IFERROR(VLOOKUP("RISOTTO AL PESTO C/ASADO",J:K,2,FALSE),0)+IFERROR(VLOOKUP("TACU TACU C/ ASADO DE RES",J:K,2,FALSE),0) -> 3 | H16: =D16-E16-F16-G16 -> 12 | J16: CEVICHE DE LENGUADO | K16: 2
A17: CUY | B17: ='23.09.25'!H17 -> 4 | C17: 4 | D17: =B17+C17 -> 8 | E17: =IFERROR(VLOOKUP("AJIACO DE CUY(1/2 CUY) C/ARROZ",J:K,2,FALSE),"0") -> 0 | H17: =D17-E17-F17-G17 -> 8 | J17: CEVICHE PESCA DEL DÌA | K17: 1
A18: ALBONDIGA | B18: ='23.09.25'!H18 -> 2 | C18: 2 | D18: =B18+C18 -> 4 | E18: =IFERROR(VLOOKUP("ALBONDIGA CON ARROZ",J:K,2,FALSE),"0") -> 1 | H18: =D18-E18-F18-G18 -> 3 | J18: CHAUFA DE LENGUADO | K18: 1
A19: ARROZ C. PATO | B19: ='23.09.25'!H19 -> 0 | C19: 10 | D19: =B19+C19 -> 10 | E19: =IFERROR(VLOOKUP("ARROZ C/PATO DESHUESADO", J:K, 2, FALSE)*2, 0)+IFERROR(VLOOKUP("ARROZ C/PATO",J:K,2,FALSE),"0") -> 9 | H19: =D19-E19-F19-G19 -> 1 | J19: CHICHARRON DE POLLO C/ PAPAS FRITAS | K19: 1
A20: CABRITO NORMAL | B20: ='23.09.25'!H20 -> 1 | C20: 40 | D20: =B20+C20 -> 41 | E20: =IFERROR(VLOOKUP("CABRITO C/ TACU TACU",J:K,2,FALSE),"0")+IFERROR(VLOOKUP("CABRITO C/ARROZ FRIJOL Y YUCA",J:K,2,FALSE),"0")+IFERROR(VLOOKUP("PRESA DE CABRITO",J:K,2,FALSE),"0")+IFERROR(VLOOKUP("CABRITO DESHUESADO",J:K,2,FALSE)*2,"0")+IFERROR(VLOOKUP("TACU TACU C/ CABRITO DESHUESADO",J:K,2,FALSE)*2,"0")+IFERROR(VLOOKUP("PIQUEO DOÑA FRESIA",J:K,2,FALSE)*2,"0") -> 32 | H20: =D20-E20-F20-G20 -> 9 | J20: CHICHARRON MIXTO DE MARISCOS | K20: 1
A21: CABRITO DESHUESADO | B21: ='23.09.25'!H21 | D21: =B21+C21 -> 0 | J21: CORVINA GUISADA C/E CHOCLO | K21: 4
A22: PATO ESTOFADO | B22: ='23.09.25'!H22 -> 19 | C22: 20 | D22: =B22+C22 -> 39 | E22: =IFERROR(VLOOKUP("PATO ESTOFADO C/ARROZ Y FRIJOL",J:K,2,FALSE),0)+IFERROR(VLOOKUP("PATO ESTOFADO DESHUESADO",J:K,2,FALSE)*2,0)+IFERROR(VLOOKUP("TACU TACU C/ PATO ESTOF. DESHUESADO",J:K,2,FALSE)*2,0)+IFERROR(VLOOKUP("PIQUEO DOÑA FRESIA",J:K,2,FALSE)*2,0)+IFERROR(VLOOKUP("PATO ESTOFADO CON TACU TACU",J:K,2,FALSE),0) -> 8 | G22: 10 | H22: =D22-E22-F22-G22 -> 21 | I22: SE DESHUESO PORQUE LAS PRESAS ESTABAN MUY CHICAS | J22: DIETA DE POLLO | K22: 1
A23: PEPIAN | B23: ='23.09.25'!H23 -> 0 | C23: 2 | D23: =B23+C23 -> 2 | E23: =IFERROR(VLOOKUP("PEPIAN DE PAVO",J:K,2,FALSE),"0")+IFERROR(VLOOKUP("PRESA DE PAVA",J:K,2,FALSE),0)+IFERROR(VLOOKUP("SANDWICH DE PAVO",J:K,2,FALSE),0) -> 2 | H23: =D23-E23-F23-G23 -> 0 | J23: ENSALADA DE PALTA | K23: 1
A24: CORVINA GUISADA | B24: ='23.09.25'!H24 -> 4 | C24: 1 | D24: =B24+C24 -> 5 | E24: =IFERROR(VLOOKUP("CORVINA GUISADA C/E CHOCLO",J:K,2,FALSE),"0") -> 4 | H24: =D24-E24-F24-G24 -> 1 | J24: FILETE DE POLLO A LA PLANCHA | K24: 5
A25: FRITURAS | J25: LENGUADO A LA PLANCHA CON ARROZ | K25: 1
A26: LOMO SALTADO | B26: ='23.09.25'!H26 -> 6.5 | C26: 1 | D26: =B26+C26 -> 7.5 | E26: =IFERROR(VLOOKUP("LOMO SALTADO C/ARROZ",J:K,2,FALSE),0)+IFERROR(VLOOKUP("TACU TACU C/ LOMO SALTADO",J:K,2,FALSE),0)+IFERROR(VLOOKUP("LOMO SALTADO A LO POBRE",J:K,2,FALSE),0)++IFERROR(VLOOKUP("FETUCCINI AL P.C/ LOMO SALTADO",J:K,2,FALSE),"0")+IFERROR(VLOOKUP("FETUCCINI A LO ALFR.C/ LOMO SALTADO",J:K,2,FALSE),"0")+IFERROR(VLOOKUP("FETUCCINI A LA H.C/ LOMO SALTADO",J:K,2,FALSE),"0")+IFERROR(VLOOKUP("RISOTTO A LA H. C/ LOMO SALTADO",J:K,2,FALSE),0)+IFERROR(VLOOKUP("RISOTTO PESTO C/LOMO SALTADO",J:K,2,FALSE),0)+IFERROR(VLOOKUP("CAUSA DE LOMO FINO SALTADO",J:K,2,FALSE)/2,0)+IFERROR(VLOOKUP("LOMO SALTADO A NUESTRO ESTILO",J:K,2,FALSE),0)+IFERROR(VLOOKUP("SANDWICH DE LOMO FINO SALTADO",J:K,2,FALSE)/2,0)+IFERROR(VLOOKUP("LOMO SALTADO C/ ARROZ Y FRIJOL",J:K,2,FALSE),0)+IFERROR(VLOOKUP("SALTADO MAR Y TIERRA ",$J:$K,2,FALSE)/2,0)+IFERROR(VLOOKUP("LOMO EN NUESTRO ESTILO",$J:$K,2,FALSE),0) -> 1 | H26: =D26-E26-F26-G26 -> 6.5 | J26: LENGUADO APANADO C/ARROZ Y FRIJOL | K26: 2
A27: FILETE DE POLLO CARTA | B27: ='23.09.25'!H27 -> 1 | C27: 5 | D27: =B27+C27 -> 6 | E27: =IFERROR(VLOOKUP("FILETE DE POLLO A LA PLANCHA",J:K,2,FALSE),"0")+IFERROR(VLOOKUP("FETUCCINI A LO ALFR.C/ FILETE DE POLLO",J:K,2,FALSE),"0")+IFERROR(VLOOKUP("FETUCCINI A LA H.C/ FILETE DE POLLO",J:K,2,FALSE),"0")+IFERROR(VLOOKUP("FETUCCINI AL P.C/ FILETE DE POLLO",J:K,2,FALSE),"0")+IFERROR(VLOOKUP("PIQUEO PERUANISIMO",J:K,2,FALSE)*2,0)+IFERROR(VLOOKUP("DIETA DE POLLO",J:K,2,FALSE),0)+IFERROR(VLOOKUP("RISOTTO PESTO C/FILETE DE POLLO",J:K,2,FALSE),0)+IFERROR(VLOOKUP("POLLO SALTADO C/ ARROZ Y PAPAS FRITAS",J:K,2,FALSE),0)+IFERROR(VLOOKUP("PRESA DE FILETE DE POLLO",J:K,2,FALSE),0)+IFERROR(VLOOKUP("SALTADO MAR Y TIERRA ",J:K,2,FALSE)/2,0)+IFERROR(VLOOKUP("CAUSA DE POLLO ",J:K,2,FALSE),0)+IFERROR(VLOOKUP("SANDWICH DE POLLO ",J:K,2,FALSE),0) -> 6 | H27: =D27-E27-F27-G27 -> 0 | J27: LENGUADO O SIMILAR AL AJO C/ARROZ | K27: 1
A28: MILANESA CARTA | B28: ='23.09.25'!H28 -> 5 | D28: =B28+C28 -> 5 | E28: =IFERROR(VLOOKUP("MILANESA DE POLLO",J:K,2,FALSE),"0")+IFERROR(VLOOKUP("FETUCCINI AL P.C/ MILANESA",J:K,2,FALSE),"0")+IFERROR(VLOOKUP("FETUCCINI A LO ALFR.C/ MILANESA",J:K,2,FALSE),"0")+IFERROR(VLOOKUP("FETUCCINI A LA H.C/ MILANESA",J:K,2,FALSE),"0")+IFERROR(VLOOKUP("MILANESA DE POLLO A LO POBRE",J:K,2,FALSE),"0")+IFERROR(VLOOKUP("RISOTTO PESTO C/MILANESA",J:K,2,FALSE),0)+IFERROR(VLOOKUP("TACU TACU C/ MILANESA",J:K,2,FALSE),0)+IFERROR(VLOOKUP("RISOTTO A LA H. C/MILANESA DE POLLO",J:K,2,FALSE),0) -> 0 | H28: =D28-E28-F28-G28 -> 5 | J28: ALBONDIGA CON ARROZ | K28: 1
A29: BISTEC CARTA | B29: ='23.09.25'!H29 -> 5 | C29: 5 | D29: =B29+C29 -> 10 | E29: =IFERROR(VLOOKUP("TACU TACU C/ BISTEC A LO POBRE",J:K,2,FALSE),0)+IFERROR(VLOOKUP("BISTEC DE LOMO FINO A LO POBRE",J:K,2,FALSE),0)+IFERROR(VLOOKUP("FETUCCINI AL P.C/ BISTEC DE LOMO 250 G",J:K,2,FALSE),"0")+IFERROR(VLOOKUP("FETUCCINI A LO ALFR.C/ BISTEC DE LOMO 250 G",J:K,2,FALSE),"0")+IFERROR(VLOOKUP("FETUCCINI A LA H.C/ BISTEC DE LOMO 250 G",J:K,2,FALSE),"0")+IFERROR(VLOOKUP("FETUCCINI AL P.C/ BISTEC DE LOMO APANADO",J:K,2,FALSE),"0")+IFERROR(VLOOKUP("FETUCCINI A LO ALFR.C/ BISTEC DE LOMO APANADO",J:K,2,FALSE),"0")+IFERROR(VLOOKUP("FETUCCINI A LA H.C/ BISTEC DE LOMO APANADO",J:K,2,FALSE),"0")+IFERROR(VLOOKUP("RISOTTO A LA H. BISTEC DE LOMO 250 G",J:K,2,FALSE),0)+IFERROR(VLOOKUP("RISOTTO PESTO C/BISTEC DE LOMO 250 G",J:K,2,FALSE),0)+IFERROR(VLOOKUP("BISTEC DE LOMO FINO A LA PLANCHA",J:K,2,FALSE),0)+IFERROR(VLOOKUP("LOMO A LAS 3 PIMIENTAS",J:K,2,FALSE),0)+IFERROR(VLOOKUP("LOMO FINO EN SALSA D CHAMPIÑONES",J:K,2,FALSE),0)+IFERROR(VLOOKUP("BISTEC DE LOMO FINO APANADO",J:K,2,FALSE),0)+IFERROR(VLOOKUP("TACU TACU C/LOMO FINO EN SALSA DE LANGOSTINOS",J:K,2,FALSE),0) -> 6 | H29: =D29-E29-F29-G29 -> 4 | J29: PALTA A LA REINA | K29: 1
A30: CHICHARRON DE POLLO | B30: ='23.09.25'!H30 -> 0 | C30: 1 | D30: =B30+C30 -> 1 | E30: =IFERROR(VLOOKUP("CHICHARRON DE POLLO C/ PAPAS FRITAS",J:K,2,FALSE),0)+IFERROR(VLOOKUP("1/2 PORC. CHICHARRON DE POLLO",J:K,2,FALSE),0) -> 1 | H30: =D30-E30-F30-G30 -> 0 | J30: PAPA A LA HUANCAINA | K30: 4
A31: PESCADOS Y MARISCOS | D31: =B31+C31 -> 0 | H31: =D31-E31-F31-G31 -> 0 | J31: PAPA RELLENA | K31: 1
A32: LENGUADO | B32: ='23.09.25'!H32 -> 25 | C32: 10 | D32: =B32+C32 -> 35 | E32: =IFERROR(VLOOKUP("CEVICHE MIXTO DE MARISCOS",J:K,2,FALSE),0)+IFERROR(VLOOKUP("CEVICHE DE LENGUADO",J:K,2,FALSE),0)+IFERROR(VLOOKUP("LENGUADO A LA PLANCHA CON ARROZ",J:K,2,FALSE),0)+IFERROR(VLOOKUP("LENGUADO A LO MACHO CON YUCA",J:K,2,FALSE),0)+IFERROR(VLOOKUP("LENGUADO APANADA C/ARROZ Y FRIJOL",J:K,2,FALSE),0)+IFERROR(VLOOKUP("LENGUADO ESCABECHADO C/ARROZ Y CAMOTE",J:K,2,FALSE),0)+IFERROR(VLOOKUP("TACU TACU C/ LENGUADO EN SALSA DE LANGOSTINOS",J:K,2,FALSE),0)+IFERROR(VLOOKUP("TACU TACU C/LENGUADO EN SALSA DE MARISCOS",J:K,2,FALSE),0)+IFERROR(VLOOKUP("TIRADITO DE LENGUADO A LAS DOS CREMAS",J:K,2,FALSE),0)+IFERROR(VLOOKUP("TIRADITO DE LENGUADO O SIMILAR",J:K,2,FALSE),0)+IFERROR(VLOOKUP("CHICHARRON DE LENGUADO",J:K,2,FALSE),0)+IFERROR(VLOOKUP("JALEA DE LENGUADO O SIMILAR",J:K,2,FALSE),0)+IFERROR(VLOOKUP("LENGUADO O CORVINA FRITA C/ARROZ Y YUCA",J:K,FALSE),0)+IFERROR(VLOOKUP("LENGUADO O CORVINA FRITA EN S/MARISCOS",J:K,2,FALSE),0)+IFERROR(VLOOKUP("LENGUADO O SIMILAR AL AJO C/ARROZ",J:K,2,FALSE),0)+IFERROR(VLOOKUP("LENGUADO A LA MEUNIERE",J:K,2,FALSE),0)+IFERROR(VLOOKUP("TACU TACU C/ LENGUADO A LO MACHO",J:K,2,FALSE),0)+IFERROR(VLOOKUP("CHICHARRON MIXTO DE MARISCOS",J:K,2,FALSE),0)+IFERROR(VLOOKUP("FUENTE DE CEVICHE DE CORVINA O LENGUADO",J:K,2,FALSE)*2,0)+IFERROR(VLOOKUP("CAUSA DE LA CASA ",J:K,2,FALSE),0)+IFERROR(VLOOKUP("TACU TACU C/ LENGUDO EN SALSA DE LANGOSTINOS",J:K,2,FALSE),0) -> 7 | H32: =D32-E32-F32-G32 -> 28 | J32: PATITA EN FIAMBRE | K32: 2.5
A33: CORVINA | B33: ='23.09.25'!H33 -> 4 | D33: =B33+C33 -> 4 | E33: =IFERROR(VLOOKUP("CORVINA SUDADA",J:K,2,FALSE),0)+IFERROR(VLOOKUP("CHUPE DE CORVINA",J:K,2,FALSE),0) -> 0 | H33: =D33-E33-F33-G33 -> 4 | J33: PATO ESTOFADO C/ARROZ Y FRIJOL | K33: 4
A34: PULPO | B34: ='23.09.25'!H34 -> 8 | D34: =B34+C34 -> 8 | E34: =IFERROR(VLOOKUP("PULPO ANTICUCHERO 250G",J:K,2,FALSE),0)+IFERROR(VLOOKUP("PULPO AL OLIVO 200G",J:K,2,FALSE),0)+IFERROR(VLOOKUP("CEVICHE DE PULPO",J:K,2,FALSE),0)+IFERROR(VLOOKUP("CAUSA DE PULPO AL OLIVO",J:K,2,FALSE),0)+IFERROR(VLOOKUP("CEVICHE DE PULPO",J:K,2,FALSE)*2,0)+IFERROR(VLOOKUP("TRES CAUSAS UNA PARRILLA",J:K,2,FALSE)/2,0) -> 3 | G34: 1 | H34: =D34-E34-F34-G34 -> 4 | I34: SE ENVIO A SAN ANDRES | J34: PATO ESTOFADO DESHUESADO | K34: 1
A35: CAMARON | B35: ='23.09.25'!H35 -> 0 | D35: =B35+C35 -> 0 | E35: =IFERROR(VLOOKUP("CHUPE DE CAMARORES",J:K,2,FALSE),0)+IFERROR(VLOOKUP("CAMARONES AL AJO",J:K,2,FALSE),0)+IFERROR(VLOOKUP("CEVICHE DE CAMARONES",J:K,2,FALSE),0)+IFERROR(VLOOKUP("ARROZ CON CAMARONES",J:K,2,FALSE),0)+IFERROR(VLOOKUP("CAUSA DE CAMARONES",J:K,2,FALSE),0) -> 0 | H35: =D35-E35-F35-G35 -> 0 | J35: PEPIAN DE PAVO | K35: 2
A36: MIXTURA | B36: ='23.09.25'!H36 -> 22 | D36: =B36+C36 -> 22 | E36: =IFERROR(VLOOKUP("PIQUEO FRUTOS DEL MAR",J:K,2,FALSE)*2,0)+IFERROR(VLOOKUP("CEVICHE MIXTO DE MARISCOS",J:K,2,FALSE),0)+IFERROR(VLOOKUP("ARROZ C/MARISCOS",J:K,2,FALSE),0)+IFERROR(VLOOKUP("TORTILLA DE MARISCOS C/ ARROZ",J:K,2,FALSE),0)+IFERROR(VLOOKUP("CHAUFA DE MARISCOS",J:K,2,FALSE),0)+IFERROR(VLOOKUP("PARIHUELA DE MARISCOS",J:K,2,FALSE),0)+IFERROR(VLOOKUP("PICANTE DE MARISCOS",J:K,2,FALSE),0)+IFERROR(VLOOKUP("TACU TACU EN SALSA DE MARISCOS",J:K,2,FALSE),0)+IFERROR(VLOOKUP("TRÍO DE CAUSAS",J:K,2,FALSE),0)+IFERROR(VLOOKUP("CHICHARRON MIXTO DE MARISCOS",J:K,2,FALSE),0)+IFERROR(VLOOKUP("LENGUADO O CORVINA FRITA EN S/MARISCOS",J:K,2,FALSE),0)+IFERROR(VLOOKUP("TACU TACU C/LENGUADO EN SALSA DE MARISCOS",J:K,2,FALSE),0)+IFERROR(VLOOKUP("RISOTTO FRUTOS DEL MAR",J:K,2,FALSE),0)+IFERROR(VLOOKUP("TRES CAUSAS UNA PARRILLA",J:K,2,FALSE)/2,0) -> 3 | G36: 3 | H36: =D36-$E$36-F36-G36 -> 16 | I36: SE UTIZO MAS POR UN RECLAMO DEL CLIENTE | J36: PORCION DE ARROZ | K36: 1
A37: TOLLO | B37: ='23.09.25'!H37 -> 7 | C37: 2 | D37: =B37+C37 -> 9 | E37: =IFERROR(VLOOKUP("PIQUEO FRUTOS DEL MAR",J:K,2,FALSE)*2,0)+IFERROR(VLOOKUP("CHICHARRON PESCA DEL DIA",J:K,2,FALSE),0)+IFERROR(VLOOKUP("CEVICHE PESCA DEL DIA",J:K,2,FALSE),0)+IFERROR(VLOOKUP("LECHE DE TIGRE",J:K,2,FALSE),0)+IFERROR(VLOOKUP("1/2 LECHE DE TIGRE",J:K,2,FALSE)/2,0)+IFERROR(VLOOKUP("TRILOGIA DE LECHES DE TIGRE ",J:K,2,FALSE),0)+IFERROR(VLOOKUP("CAUSA EN SALSA ACEVICHADA ",J:K,2,FALSE),0)+IFERROR(VLOOKUP("CAUSA DE LA CASA",J:K,2,FALSE),0) -> 2 | H37: =D37-$E$36-F37-G37 -> 6 | J37: PULPO ANTICUCHERO 250G | K37: 1
